Workbook

Sheet Sheet
A1: ID | B1: sex | C1: age | D1: lifestyle | E1: job | F1: salary | G1: city | H1: expectations | I1: больше 1.5 кг хлебобулочных изделий и круп | J1: больше 1.2 кг картофеля | K1: больше 1.3 кг овощей | L1: больше 700 г фруктов | M1: больше 300 г сахара | N1: больше 700 г мяса | O1: больше 200 г рыбы | P1: больше 3.5 кг молочных продуктов | Q1: больше 3 яиц | R1: больше 150 г масла и жиров | S1: больше 60 г чая и специй | T1: крупа в неделю | U1: Картофель в неделю | V1: Овощи в неделю | W1: фрукты в неделю | X1: сахар в неделю | Y1: мясо в неделю | Z1: рыба в неделю | AA1: молоко в неделю | AB1: яйца в неделю | AC1: масло в неделю | AD1: чай в неделю | AE1: сумма в неделю | AF1: сумма в месяц на продукты | AG1: сумма потребительской корзины | AH1: official | AI1: official_difference | AJ1: mind_difference
A2: 1995902821 | B2: Жен | C2: 20 | D2: active | E2: Да | F2: 60000 | G2: Москва | H2: 7500 | I2: Да | J2: Нет | K2: Да | L2: Нет | M2: Да | N2: Да | O2: Нет | P2: Нет | Q2: Нет | R2: Да | S2: Нет | T2: =IF($G2="Москва",1.3*(IF(IF(I2="Да",1,0)=1,1.4*Лист2!AX$1,Лист2!AX$1)),(IF(IF(I2="Да",1,0)=1,1.4*Лист2!AX$1,Лист2!AX$1))) -> 396.9 | U2: =IF($G2="Москва",1.3*(IF(IF(J2="Да",1,0)=1,1.4*Лист2!AY$1,Лист2!AY$1)),(IF(IF(J2="Да",1,0)=1,1.4*Лист2!AY$1,Лист2!AY$1))) -> 250 | V2: =IF($G2="Москва",1.3*(IF(IF(K2="Да",1,0)=1,1.4*Лист2!AZ$1,Лист2!AZ$1)),(IF(IF(K2="Да",1,0)=1,1.4*Лист2!AZ$1,Лист2!AZ$1))) -> 1197 | W2: =IF($G2="Москва",1.3*(IF(IF(L2="Да",1,0)=1,1.4*Лист2!BA$1,Лист2!BA$1)),(IF(IF(L2="Да",1,0)=1,1.4*Лист2!BA$1,Лист2!BA$1))) -> 300 | X2: =IF($G2="Москва",1.3*(IF(IF(M2="Да",1,0)=1,1.4*Лист2!BB$1,Лист2!BB$1)),(IF(IF(M2="Да",1,0)=1,1.4*Лист2!BB$1,Лист2!BB$1))) -> 64.4 | Y2: =IF($G2="Москва",1.3*(IF(IF(N2="Да",1,0)=1,1.4*Лист2!BC$1,Лист2!BC$1)),(IF(IF(N2="Да",1,0)=1,1.4*Лист2!BC$1,Лист2!BC$1))) -> 1218 | Z2: =IF($G2="Москва",1.3*(IF(IF(O2="Да",1,0)=1,1.4*Лист2!BD$1,Лист2!BD$1)),(IF(IF(O2="Да",1,0)=1,1.4*Лист2!BD$1,Лист2!BD$1))) -> 315 | AA2: =IF($G2="Москва",1.3*(IF(IF(P2="Да",1,0)=1,1.4*Лист2!BE$1,Лист2!BE$1)),(IF(IF(P2="Да",1,0)=1,1.4*Лист2!BE$1,Лист2!BE$1))) -> 725 | ... AD2: =IF($G2="Москва",1.3*(IF(IF(S2="Да",1,0)=1,1.4*Лист2!BH$1,Лист2!BH$1)),(IF(IF(S2="Да",1,0)=1,1.4*Лист2!BH$1,Лист2!BH$1))) -> 156.25 | AE2: =SUM(T2:AD2) -> 4739.45 | AF2: =AE2*4.2 -> 19905.69 | AG2: =AF2*2 -> 39811.38 | AH2: =IF(IF(G2="Москва",1,0)=1,Лист2!$BK$6,Лист2!$BL$6) -> 13651 | AI2: =AH2-AF2 -> -6254.69 | AJ2: =(H2-AE2)*4.2 -> 11594.31
A3: 1996067555 | B3: Муж | C3: 35 | D3: medium | E3: Да | F3: 30000 | G3: Москва | H3: 8000 | I3: Да | J3: Нет | K3: Нет | L3: Нет | M3: Нет | N3: Да | O3: Нет | P3: Да | Q3: Да | R3: Нет | S3: Нет | T3: =IF($G3="Москва",1.3*(IF(IF(I3="Да",1,0)=1,1.4*Лист2!AX$1,Лист2!AX$1)),(IF(IF(I3="Да",1,0)=1,1.4*Лист2!AX$1,Лист2!AX$1))) -> 396.9 | U3: =IF($G3="Москва",1.3*(IF(IF(J3="Да",1,0)=1,1.4*Лист2!AY$1,Лист2!AY$1)),(IF(IF(J3="Да",1,0)=1,1.4*Лист2!AY$1,Лист2!AY$1))) -> 250 | V3: =IF($G3="Москва",1.3*(IF(IF(K3="Да",1,0)=1,1.4*Лист2!AZ$1,Лист2!AZ$1)),(IF(IF(K3="Да",1,0)=1,1.4*Лист2!AZ$1,Лист2!AZ$1))) -> 855 | W3: =IF($G3="Москва",1.3*(IF(IF(L3="Да",1,0)=1,1.4*Лист2!BA$1,Лист2!BA$1)),(IF(IF(L3="Да",1,0)=1,1.4*Лист2!BA$1,Лист2!BA$1))) -> 300 | X3: =IF($G3="Москва",1.3*(IF(IF(M3="Да",1,0)=1,1.4*Лист2!BB$1,Лист2!BB$1)),(IF(IF(M3="Да",1,0)=1,1.4*Лист2!BB$1,Лист2!BB$1))) -> 46 | Y3: =IF($G3="Москва",1.3*(IF(IF(N3="Да",1,0)=1,1.4*Лист2!BC$1,Лист2!BC$1)),(IF(IF(N3="Да",1,0)=1,1.4*Лист2!BC$1,Лист2!BC$1))) -> 1218 | Z3: =IF($G3="Москва",1.3*(IF(IF(O3="Да",1,0)=1,1.4*Лист2!BD$1,Лист2!BD$1)),(IF(IF(O3="Да",1,0)=1,1.4*Лист2!BD$1,Лист2!BD$1))) -> 315 | AA3: =IF($G3="Москва",1.3*(IF(IF(P3="Да",1,0)=1,1.4*Лист2!BE$1,Лист2!BE$1)),(IF(IF(P3="Да",1,0)=1,1.4*Лист2!BE$1,Лист2!BE$1))) -> 1015 | ... AD3: =IF($G3="Москва",1.3*(IF(IF(S3="Да",1,0)=1,1.4*Лист2!BH$1,Лист2!BH$1)),(IF(IF(S3="Да",1,0)=1,1.4*Лист2!BH$1,Лист2!BH$1))) -> 156.25 | AE3: =SUM(T3:AD3) -> 4678.85 | AF3: =AE3*4.2 -> 19651.17 | AG3: =AF3*2 -> 39302.34 | AH3: =IF(IF(G3="Москва",1,0)=1,Лист2!$BK$6,Лист2!$BL$6) -> 13651 | AI3: =AH3-AF3 -> -6000.17 | AJ3: =(H3-AE3)*4.2 -> 13948.83
A4: 1996071674 | B4: Муж | C4: 20 | D4: active | E4: Нет | F4: 60000 | G4: Москва | H4: 8000 | I4: Да | J4: Нет | K4: Да | L4: Нет | M4: Да | N4: Да | O4: Нет | P4: Да | Q4: Да | R4: Нет | S4: Да | T4: =IF($G4="Москва",1.3*(IF(IF(I4="Да",1,0)=1,1.4*Лист2!AX$1,Лист2!AX$1)),(IF(IF(I4="Да",1,0)=1,1.4*Лист2!AX$1,Лист2!AX$1))) -> 396.9 | U4: =IF($G4="Москва",1.3*(IF(IF(J4="Да",1,0)=1,1.4*Лист2!AY$1,Лист2!AY$1)),(IF(IF(J4="Да",1,0)=1,1.4*Лист2!AY$1,Лист2!AY$1))) -> 250 | V4: =IF($G4="Москва",1.3*(IF(IF(K4="Да",1,0)=1,1.4*Лист2!AZ$1,Лист2!AZ$1)),(IF(IF(K4="Да",1,0)=1,1.4*Лист2!AZ$1,Лист2!AZ$1))) -> 1197 | W4: =IF($G4="Москва",1.3*(IF(IF(L4="Да",1,0)=1,1.4*Лист2!BA$1,Лист2!BA$1)),(IF(IF(L4="Да",1,0)=1,1.4*Лист2!BA$1,Лист2!BA$1))) -> 300 | X4: =IF($G4="Москва",1.3*(IF(IF(M4="Да",1,0)=1,1.4*Лист2!BB$1,Лист2!BB$1)),(IF(IF(M4="Да",1,0)=1,1.4*Лист2!BB$1,Лист2!BB$1))) -> 64.4 | Y4: =IF($G4="Москва",1.3*(IF(IF(N4="Да",1,0)=1,1.4*Лист2!BC$1,Лист2!BC$1)),(IF(IF(N4="Да",1,0)=1,1.4*Лист2!BC$1,Лист2!BC$1))) -> 1218 | Z4: =IF($G4="Москва",1.3*(IF(IF(O4="Да",1,0)=1,1.4*Лист2!BD$1,Лист2!BD$1)),(IF(IF(O4="Да",1,0)=1,1.4*Лист2!BD$1,Лист2!BD$1))) -> 315 | AA4: =IF($G4="Москва",1.3*(IF(IF(P4="Да",1,0)=1,1.4*Лист2!BE$1,Лист2!BE$1)),(IF(IF(P4="Да",1,0)=1,1.4*Лист2!BE$1,Лист2!BE$1))) -> 1015 | ... AD4: =IF($G4="Москва",1.3*(IF(IF(S4="Да",1,0)=1,1.4*Лист2!BH$1,Лист2!BH$1)),(IF(IF(S4="Да",1,0)=1,1.4*Лист2!BH$1,Лист2!BH$1))) -> 218.75 | AE4: =SUM(T4:AD4) -> 5101.75 | AF4: =AE4*4.2 -> 21427.35 | AG4: =AF4*2 -> 42854.7 | AH4: =IF(IF(G4="Москва",1,0)=1,Лист2!$BK$6,Лист2!$BL$6) -> 13651 | AI4: =AH4-AF4 -> -7776.35 | AJ4: =(H4-AE4)*4.2 -> 12172.65
A5: 1996073501 | B5: Муж | C5: 20 | D5: active | E5: Да | F5: 60000 | G5: Саратов, Саратовская область | H5: 4000 | I5: Да | J5: Нет | K5: Да | L5: Да | M5: Нет | N5: Да | O5: Да | P5: Нет | Q5: Да | R5: Нет | S5: Нет | T5: =IF($G5="Москва",1.3*(IF(IF(I5="Да",1,0)=1,1.4*Лист2!AX$1,Лист2!AX$1)),(IF(IF(I5="Да",1,0)=1,1.4*Лист2!AX$1,Лист2!AX$1))) -> 305.30769 | U5: =IF($G5="Москва",1.3*(IF(IF(J5="Да",1,0)=1,1.4*Лист2!AY$1,Лист2!AY$1)),(IF(IF(J5="Да",1,0)=1,1.4*Лист2!AY$1,Лист2!AY$1))) -> 192.30769 | V5: =IF($G5="Москва",1.3*(IF(IF(K5="Да",1,0)=1,1.4*Лист2!AZ$1,Лист2!AZ$1)),(IF(IF(K5="Да",1,0)=1,1.4*Лист2!AZ$1,Лист2!AZ$1))) -> 920.76923 | W5: =IF($G5="Москва",1.3*(IF(IF(L5="Да",1,0)=1,1.4*Лист2!BA$1,Лист2!BA$1)),(IF(IF(L5="Да",1,0)=1,1.4*Лист2!BA$1,Лист2!BA$1))) -> 323.07692 | X5: =IF($G5="Москва",1.3*(IF(IF(M5="Да",1,0)=1,1.4*Лист2!BB$1,Лист2!BB$1)),(IF(IF(M5="Да",1,0)=1,1.4*Лист2!BB$1,Лист2!BB$1))) -> 35.384615 | Y5: =IF($G5="Москва",1.3*(IF(IF(N5="Да",1,0)=1,1.4*Лист2!BC$1,Лист2!BC$1)),(IF(IF(N5="Да",1,0)=1,1.4*Лист2!BC$1,Лист2!BC$1))) -> 936.92308 | Z5: =IF($G5="Москва",1.3*(IF(IF(O5="Да",1,0)=1,1.4*Лист2!BD$1,Лист2!BD$1)),(IF(IF(O5="Да",1,0)=1,1.4*Лист2!BD$1,Лист2!BD$1))) -> 339.23077 | AA5: =IF($G5="Москва",1.3*(IF(IF(P5="Да",1,0)=1,1.4*Лист2!BE$1,Лист2!BE$1)),(IF(IF(P5="Да",1,0)=1,1.4*Лист2!BE$1,Лист2!BE$1))) -> 557.69231 | ... AD5: =IF($G5="Москва",1.3*(IF(IF(S5="Да",1,0)=1,1.4*Лист2!BH$1,Лист2!BH$1)),(IF(IF(S5="Да",1,0)=1,1.4*Лист2!BH$1,Лист2!BH$1))) -> 120.19231 | AE5: =SUM(T5:AD5) -> 3828.3462 | AF5: =AE5*4.2 -> 16079.054 | AG5: =AF5*2 -> 32158.108 | AH5: =IF(IF(G5="Москва",1,0)=1,Лист2!$BK$6,Лист2!$BL$6) -> 9230 | AI5: =AH5-AF5 -> -6849.0538 | AJ5: =(H5-AE5)*4.2 -> 720.94615
A6: 1996076712 | B6: Муж | C6: 20 | D6: active | E6: Да | F6: 60000 | G6: Москва | H6: 5000 | I6: Нет | J6: Да | K6: Да | L6: Да | M6: Нет | N6: Да | O6: Да | P6: Да | Q6: Да | R6: Нет | S6: Нет | T6: =IF($G6="Москва",1.3*(IF(IF(I6="Да",1,0)=1,1.4*Лист2!AX$1,Лист2!AX$1)),(IF(IF(I6="Да",1,0)=1,1.4*Лист2!AX$1,Лист2!AX$1))) -> 283.5 | U6: =IF($G6="Москва",1.3*(IF(IF(J6="Да",1,0)=1,1.4*Лист2!AY$1,Лист2!AY$1)),(IF(IF(J6="Да",1,0)=1,1.4*Лист2!AY$1,Лист2!AY$1))) -> 350 | V6: =IF($G6="Москва",1.3*(IF(IF(K6="Да",1,0)=1,1.4*Лист2!AZ$1,Лист2!AZ$1)),(IF(IF(K6="Да",1,0)=1,1.4*Лист2!AZ$1,Лист2!AZ$1))) -> 1197 | W6: =IF($G6="Москва",1.3*(IF(IF(L6="Да",1,0)=1,1.4*Лист2!BA$1,Лист2!BA$1)),(IF(IF(L6="Да",1,0)=1,1.4*Лист2!BA$1,Лист2!BA$1))) -> 420 | X6: =IF($G6="Москва",1.3*(IF(IF(M6="Да",1,0)=1,1.4*Лист2!BB$1,Лист2!BB$1)),(IF(IF(M6="Да",1,0)=1,1.4*Лист2!BB$1,Лист2!BB$1))) -> 46 | Y6: =IF($G6="Москва",1.3*(IF(IF(N6="Да",1,0)=1,1.4*Лист2!BC$1,Лист2!BC$1)),(IF(IF(N6="Да",1,0)=1,1.4*Лист2!BC$1,Лист2!BC$1))) -> 1218 | Z6: =IF($G6="Москва",1.3*(IF(IF(O6="Да",1,0)=1,1.4*Лист2!BD$1,Лист2!BD$1)),(IF(IF(O6="Да",1,0)=1,1.4*Лист2!BD$1,Лист2!BD$1))) -> 441 | AA6: =IF($G6="Москва",1.3*(IF(IF(P6="Да",1,0)=1,1.4*Лист2!BE$1,Лист2!BE$1)),(IF(IF(P6="Да",1,0)=1,1.4*Лист2!BE$1,Лист2!BE$1))) -> 1015 | ... AD6: =IF($G6="Москва",1.3*(IF(IF(S6="Да",1,0)=1,1.4*Лист2!BH$1,Лист2!BH$1)),(IF(IF(S6="Да",1,0)=1,1.4*Лист2!BH$1,Лист2!BH$1))) -> 156.25 | AE6: =SUM(T6:AD6) -> 5253.45 | AF6: =AE6*4.2 -> 22064.49 | AG6: =AF6*2 -> 44128.98 | AH6: =IF(IF(G6="Москва",1,0)=1,Лист2!$BK$6,Лист2!$BL$6) -> 13651 | AI6: =AH6-AF6 -> -8413.49 | AJ6: =(H6-AE6)*4.2 -> -1064.49
A7: 1996077733 | B7: Муж | C7: 20 | D7: medium | E7: Да | F7: 21000 | G7: Ярославль, Ярославская область | H7: 5000 | I7: Нет | J7: Нет | K7: Да | L7: Да | M7: Да | N7: Да | O7: Да | P7: Да | Q7: Да | R7: Нет | S7: Да | T7: =IF($G7="Москва",1.3*(IF(IF(I7="Да",1,0)=1,1.4*Лист2!AX$1,Лист2!AX$1)),(IF(IF(I7="Да",1,0)=1,1.4*Лист2!AX$1,Лист2!AX$1))) -> 218.07692 | U7: =IF($G7="Москва",1.3*(IF(IF(J7="Да",1,0)=1,1.4*Лист2!AY$1,Лист2!AY$1)),(IF(IF(J7="Да",1,0)=1,1.4*Лист2!AY$1,Лист2!AY$1))) -> 192.30769 | V7: =IF($G7="Москва",1.3*(IF(IF(K7="Да",1,0)=1,1.4*Лист2!AZ$1,Лист2!AZ$1)),(IF(IF(K7="Да",1,0)=1,1.4*Лист2!AZ$1,Лист2!AZ$1))) -> 920.76923 | W7: =IF($G7="Москва",1.3*(IF(IF(L7="Да",1,0)=1,1.4*Лист2!BA$1,Лист2!BA$1)),(IF(IF(L7="Да",1,0)=1,1.4*Лист2!BA$1,Лист2!BA$1))) -> 323.07692 | X7: =IF($G7="Москва",1.3*(IF(IF(M7="Да",1,0)=1,1.4*Лист2!BB$1,Лист2!BB$1)),(IF(IF(M7="Да",1,0)=1,1.4*Лист2!BB$1,Лист2!BB$1))) -> 49.538462 | Y7: =IF($G7="Москва",1.3*(IF(IF(N7="Да",1,0)=1,1.4*Лист2!BC$1,Лист2!BC$1)),(IF(IF(N7="Да",1,0)=1,1.4*Лист2!BC$1,Лист2!BC$1))) -> 936.92308 | Z7: =IF($G7="Москва",1.3*(IF(IF(O7="Да",1,0)=1,1.4*Лист2!BD$1,Лист2!BD$1)),(IF(IF(O7="Да",1,0)=1,1.4*Лист2!BD$1,Лист2!BD$1))) -> 339.23077 | AA7: =IF($G7="Москва",1.3*(IF(IF(P7="Да",1,0)=1,1.4*Лист2!BE$1,Лист2!BE$1)),(IF(IF(P7="Да",1,0)=1,1.4*Лист2!BE$1,Лист2!BE$1))) -> 780.76923 | ... AD7: =IF($G7="Москва",1.3*(IF(IF(S7="Да",1,0)=1,1.4*Лист2!BH$1,Лист2!BH$1)),(IF(IF(S7="Да",1,0)=1,1.4*Лист2!BH$1,Лист2!BH$1))) -> 168.26923 | AE7: =SUM(T7:AD7) -> 4026.4231 | AF7: =AE7*4.2 -> 16910.977 | AG7: =AF7*2 -> 33821.954 | AH7: =IF(IF(G7="Москва",1,0)=1,Лист2!$BK$6,Лист2!$BL$6) -> 9230 | AI7: =AH7-AF7 -> -7680.9769 | AJ7: =(H7-AE7)*4.2 -> 4089.0231
A8: 1996080122 | B8: Жен | C8: 20 | D8: active | E8: Нет | F8: 12000 | G8: Москва | H8: 3000 | I8: Нет | J8: Нет | K8: Да | L8: Да | M8: Нет | N8: Да | O8: Нет | P8: Нет | Q8: Да | R8: Нет | S8: Да | T8: =IF($G8="Москва",1.3*(IF(IF(I8="Да",1,0)=1,1.4*Лист2!AX$1,Лист2!AX$1)),(IF(IF(I8="Да",1,0)=1,1.4*Лист2!AX$1,Лист2!AX$1))) -> 283.5 | U8: =IF($G8="Москва",1.3*(IF(IF(J8="Да",1,0)=1,1.4*Лист2!AY$1,Лист2!AY$1)),(IF(IF(J8="Да",1,0)=1,1.4*Лист2!AY$1,Лист2!AY$1))) -> 250 | V8: =IF($G8="Москва",1.3*(IF(IF(K8="Да",1,0)=1,1.4*Лист2!AZ$1,Лист2!AZ$1)),(IF(IF(K8="Да",1,0)=1,1.4*Лист2!AZ$1,Лист2!AZ$1))) -> 1197 | W8: =IF($G8="Москва",1.3*(IF(IF(L8="Да",1,0)=1,1.4*Лист2!BA$1,Лист2!BA$1)),(IF(IF(L8="Да",1,0)=1,1.4*Лист2!BA$1,Лист2!BA$1))) -> 420 | X8: =IF($G8="Москва",1.3*(IF(IF(M8="Да",1,0)=1,1.4*Лист2!BB$1,Лист2!BB$1)),(IF(IF(M8="Да",1,0)=1,1.4*Лист2!BB$1,Лист2!BB$1))) -> 46 | Y8: =IF($G8="Москва",1.3*(IF(IF(N8="Да",1,0)=1,1.4*Лист2!BC$1,Лист2!BC$1)),(IF(IF(N8="Да",1,0)=1,1.4*Лист2!BC$1,Лист2!BC$1))) -> 1218 | Z8: =IF($G8="Москва",1.3*(IF(IF(O8="Да",1,0)=1,1.4*Лист2!BD$1,Лист2!BD$1)),(IF(IF(O8="Да",1,0)=1,1.4*Лист2!BD$1,Лист2!BD$1))) -> 315 | AA8: =IF($G8="Москва",1.3*(IF(IF(P8="Да",1,0)=1,1.4*Лист2!BE$1,Лист2!BE$1)),(IF(IF(P8="Да",1,0)=1,1.4*Лист2!BE$1,Лист2!BE$1))) -> 725 | ... AD8: =IF($G8="Москва",1.3*(IF(IF(S8="Да",1,0)=1,1.4*Лист2!BH$1,Лист2!BH$1)),(IF(IF(S8="Да",1,0)=1,1.4*Лист2!BH$1,Лист2!BH$1))) -> 218.75 | AE8: =SUM(T8:AD8) -> 4799.95 | AF8: =AE8*4.2 -> 20159.79 | AG8: =AF8*2 -> 40319.58 | AH8: =IF(IF(G8="Москва",1,0)=1,Лист2!$BK$6,Лист2!$BL$6) -> 13651 | AI8: =AH8-AF8 -> -6508.79 | AJ8: =(H8-AE8)*4.2 -> -7559.79
A9: 1996092424 | B9: Муж | C9: 20 | D9: active | E9: Да | F9: 60000 | G9: Иркутск, Иркутская область | H9: 4000 | I9: Да | J9: Нет | K9: Да | L9: Да | M9: Нет | N9: Да | O9: Нет | P9: Нет | Q9: Да | R9: Нет | S9: Да | T9: =IF($G9="Москва",1.3*(IF(IF(I9="Да",1,0)=1,1.4*Лист2!AX$1,Лист2!AX$1)),(IF(IF(I9="Да",1,0)=1,1.4*Лист2!AX$1,Лист2!AX$1))) -> 305.30769 | U9: =IF($G9="Москва",1.3*(IF(IF(J9="Да",1,0)=1,1.4*Лист2!AY$1,Лист2!AY$1)),(IF(IF(J9="Да",1,0)=1,1.4*Лист2!AY$1,Лист2!AY$1))) -> 192.30769 | V9: =IF($G9="Москва",1.3*(IF(IF(K9="Да",1,0)=1,1.4*Лист2!AZ$1,Лист2!AZ$1)),(IF(IF(K9="Да",1,0)=1,1.4*Лист2!AZ$1,Лист2!AZ$1))) -> 920.76923 | W9: =IF($G9="Москва",1.3*(IF(IF(L9="Да",1,0)=1,1.4*Лист2!BA$1,Лист2!BA$1)),(IF(IF(L9="Да",1,0)=1,1.4*Лист2!BA$1,Лист2!BA$1))) -> 323.07692 | X9: =IF($G9="Москва",1.3*(IF(IF(M9="Да",1,0)=1,1.4*Лист2!BB$1,Лист2!BB$1)),(IF(IF(M9="Да",1,0)=1,1.4*Лист2!BB$1,Лист2!BB$1))) -> 35.384615 | Y9: =IF($G9="Москва",1.3*(IF(IF(N9="Да",1,0)=1,1.4*Лист2!BC$1,Лист2!BC$1)),(IF(IF(N9="Да",1,0)=1,1.4*Лист2!BC$1,Лист2!BC$1))) -> 936.92308 | Z9: =IF($G9="Москва",1.3*(IF(IF(O9="Да",1,0)=1,1.4*Лист2!BD$1,Лист2!BD$1)),(IF(IF(O9="Да",1,0)=1,1.4*Лист2!BD$1,Лист2!BD$1))) -> 242.30769 | AA9: =IF($G9="Москва",1.3*(IF(IF(P9="Да",1,0)=1,1.4*Лист2!BE$1,Лист2!BE$1)),(IF(IF(P9="Да",1,0)=1,1.4*Лист2!BE$1,Лист2!BE$1))) -> 557.69231 | ... AD9: =IF($G9="Москва",1.3*(IF(IF(S9="Да",1,0)=1,1.4*Лист2!BH$1,Лист2!BH$1)),(IF(IF(S9="Да",1,0)=1,1.4*Лист2!BH$1,Лист2!BH$1))) -> 168.26923 | AE9: =SUM(T9:AD9) -> 3779.5 | AF9: =AE9*4.2 -> 15873.9 | AG9: =AF9*2 -> 31747.8 | AH9: =IF(IF(G9="Москва",1,0)=1,Лист2!$BK$6,Лист2!$BL$6) -> 9230 | AI9: =AH9-AF9 -> -6643.9 | AJ9: =(H9-AE9)*4.2 -> 926.1
A10: 1996104494 | B10: Муж | C10: 20 | D10: medium | E10: Да | F10: 60000 | G10: Москва | H10: 9000 | I10: Да | J10: Нет | K10: Нет | L10: Нет | M10: Да | N10: Да | O10: Нет | P10: Нет | Q10: Да | R10: Нет | S10: Да | T10: =IF($G10="Москва",1.3*(IF(IF(I10="Да",1,0)=1,1.4*Лист2!AX$1,Лист2!AX$1)),(IF(IF(I10="Да",1,0)=1,1.4*Лист2!AX$1,Лист2!AX$1))) -> 396.9 | U10: =IF($G10="Москва",1.3*(IF(IF(J10="Да",1,0)=1,1.4*Лист2!AY$1,Лист2!AY$1)),(IF(IF(J10="Да",1,0)=1,1.4*Лист2!AY$1,Лист2!AY$1))) -> 250 | V10: =IF($G10="Москва",1.3*(IF(IF(K10="Да",1,0)=1,1.4*Лист2!AZ$1,Лист2!AZ$1)),(IF(IF(K10="Да",1,0)=1,1.4*Лист2!AZ$1,Лист2!AZ$1))) -> 855 | W10: =IF($G10="Москва",1.3*(IF(IF(L10="Да",1,0)=1,1.4*Лист2!BA$1,Лист2!BA$1)),(IF(IF(L10="Да",1,0)=1,1.4*Лист2!BA$1,Лист2!BA$1))) -> 300 | X10: =IF($G10="Москва",1.3*(IF(IF(M10="Да",1,0)=1,1.4*Лист2!BB$1,Лист2!BB$1)),(IF(IF(M10="Да",1,0)=1,1.4*Лист2!BB$1,Лист2!BB$1))) -> 64.4 | Y10: =IF($G10="Москва",1.3*(IF(IF(N10="Да",1,0)=1,1.4*Лист2!BC$1,Лист2!BC$1)),(IF(IF(N10="Да",1,0)=1,1.4*Лист2!BC$1,Лист2!BC$1))) -> 1218 | Z10: =IF($G10="Москва",1.3*(IF(IF(O10="Да",1,0)=1,1.4*Лист2!BD$1,Лист2!BD$1)),(IF(IF(O10="Да",1,0)=1,1.4*Лист2!BD$1,Лист2!BD$1))) -> 315 | AA10: =IF($G10="Москва",1.3*(IF(IF(P10="Да",1,0)=1,1.4*Лист2!BE$1,Лист2!BE$1)),(IF(IF(P10="Да",1,0)=1,1.4*Лист2!BE$1,Лист2!BE$1))) -> 725 | ... AD10: =IF($G10="Москва",1.3*(IF(IF(S10="Да",1,0)=1,1.4*Лист2!BH$1,Лист2!BH$1)),(IF(IF(S10="Да",1,0)=1,1.4*Лист2!BH$1,Лист2!BH$1))) -> 218.75 | AE10: =SUM(T10:AD10) -> 4469.75 | AF10: =AE10*4.2 -> 18772.95 | AG10: =AF10*2 -> 37545.9 | AH10: =IF(IF(G10="Москва",1,0)=1,Лист2!$BK$6,Лист2!$BL$6) -> 13651 | AI10: =AH10-AF10 -> -5121.95 | AJ10: =(H10-AE10)*4.2 -> 19027.05
A11: 1996106993 | B11: Жен | C11: 20 | D11: passive | E11: Нет | F11: 12000 | G11: Екатеринбург, Свердловская область | H11: 20000 | I11: Нет | J11: Нет | K11: Нет | L11: Нет | M11: Да | N11: Да | O11: Нет | P11: Нет | Q11: Нет | R11: Да | S11: Нет | T11: =IF($G11="Москва",1.3*(IF(IF(I11="Да",1,0)=1,1.4*Лист2!AX$1,Лист2!AX$1)),(IF(IF(I11="Да",1,0)=1,1.4*Лист2!AX$1,Лист2!AX$1))) -> 218.07692 | U11: =IF($G11="Москва",1.3*(IF(IF(J11="Да",1,0)=1,1.4*Лист2!AY$1,Лист2!AY$1)),(IF(IF(J11="Да",1,0)=1,1.4*Лист2!AY$1,Лист2!AY$1))) -> 192.30769 | V11: =IF($G11="Москва",1.3*(IF(IF(K11="Да",1,0)=1,1.4*Лист2!AZ$1,Лист2!AZ$1)),(IF(IF(K11="Да",1,0)=1,1.4*Лист2!AZ$1,Лист2!AZ$1))) -> 657.69231 | W11: =IF($G11="Москва",1.3*(IF(IF(L11="Да",1,0)=1,1.4*Лист2!BA$1,Лист2!BA$1)),(IF(IF(L11="Да",1,0)=1,1.4*Лист2!BA$1,Лист2!BA$1))) -> 230.76923 | X11: =IF($G11="Москва",1.3*(IF(IF(M11="Да",1,0)=1,1.4*Лист2!BB$1,Лист2!BB$1)),(IF(IF(M11="Да",1,0)=1,1.4*Лист2!BB$1,Лист2!BB$1))) -> 49.538462 | Y11: =IF($G11="Москва",1.3*(IF(IF(N11="Да",1,0)=1,1.4*Лист2!BC$1,Лист2!BC$1)),(IF(IF(N11="Да",1,0)=1,1.4*Лист2!BC$1,Лист2!BC$1))) -> 936.92308 | Z11: =IF($G11="Москва",1.3*(IF(IF(O11="Да",1,0)=1,1.4*Лист2!BD$1,Лист2!BD$1)),(IF(IF(O11="Да",1,0)=1,1.4*Лист2!BD$1,Лист2!BD$1))) -> 242.30769 | AA11: =IF($G11="Москва",1.3*(IF(IF(P11="Да",1,0)=1,1.4*Лист2!BE$1,Лист2!BE$1)),(IF(IF(P11="Да",1,0)=1,1.4*Лист2!BE$1,Лист2!BE$1))) -> 557.69231 | ... AD11: =IF($G11="Москва",1.3*(IF(IF(S11="Да",1,0)=1,1.4*Лист2!BH$1,Лист2!BH$1)),(IF(IF(S11="Да",1,0)=1,1.4*Лист2!BH$1,Лист2!BH$1))) -> 120.19231 | AE11: =SUM(T11:AD11) -> 3295.4231 | AF11: =AE11*4.2 -> 13840.777 | AG11: =AF11*2 -> 27681.554 | AH11: =IF(IF(G11="Москва",1,0)=1,Лист2!$BK$6,Лист2!$BL$6) -> 9230 | AI11: =AH11-AF11 -> -4610.7769 | AJ11: =(H11-AE11)*4.2 -> 70159.223
A12: 1996114680 | B12: Жен | C12: 20 | D12: active | E12: Да | F12: 21000 | G12: Волжский, Волгоградская область | H12: 5000 | I12: Нет | J12: Да | K12: Нет | L12: Нет | M12: Да | N12: Да | O12: Да | P12: Нет | Q12: Да | R12: Да | S12: Да | T12: =IF($G12="Москва",1.3*(IF(IF(I12="Да",1,0)=1,1.4*Лист2!AX$1,Лист2!AX$1)),(IF(IF(I12="Да",1,0)=1,1.4*Лист2!AX$1,Лист2!AX$1))) -> 218.07692 | U12: =IF($G12="Москва",1.3*(IF(IF(J12="Да",1,0)=1,1.4*Лист2!AY$1,Лист2!AY$1)),(IF(IF(J12="Да",1,0)=1,1.4*Лист2!AY$1,Лист2!AY$1))) -> 269.23077 | V12: =IF($G12="Москва",1.3*(IF(IF(K12="Да",1,0)=1,1.4*Лист2!AZ$1,Лист2!AZ$1)),(IF(IF(K12="Да",1,0)=1,1.4*Лист2!AZ$1,Лист2!AZ$1))) -> 657.69231 | W12: =IF($G12="Москва",1.3*(IF(IF(L12="Да",1,0)=1,1.4*Лист2!BA$1,Лист2!BA$1)),(IF(IF(L12="Да",1,0)=1,1.4*Лист2!BA$1,Лист2!BA$1))) -> 230.76923 | X12: =IF($G12="Москва",1.3*(IF(IF(M12="Да",1,0)=1,1.4*Лист2!BB$1,Лист2!BB$1)),(IF(IF(M12="Да",1,0)=1,1.4*Лист2!BB$1,Лист2!BB$1))) -> 49.538462 | Y12: =IF($G12="Москва",1.3*(IF(IF(N12="Да",1,0)=1,1.4*Лист2!BC$1,Лист2!BC$1)),(IF(IF(N12="Да",1,0)=1,1.4*Лист2!BC$1,Лист2!BC$1))) -> 936.92308 | Z12: =IF($G12="Москва",1.3*(IF(IF(O12="Да",1,0)=1,1.4*Лист2!BD$1,Лист2!BD$1)),(IF(IF(O12="Да",1,0)=1,1.4*Лист2!BD$1,Лист2!BD$1))) -> 339.23077 | AA12: =IF($G12="Москва",1.3*(IF(IF(P12="Да",1,0)=1,1.4*Лист2!BE$1,Лист2!BE$1)),(IF(IF(P12="Да",1,0)=1,1.4*Лист2!BE$1,Лист2!BE$1))) -> 557.69231 | ... AD12: =IF($G12="Москва",1.3*(IF(IF(S12="Да",1,0)=1,1.4*Лист2!BH$1,Лист2!BH$1)),(IF(IF(S12="Да",1,0)=1,1.4*Лист2!BH$1,Лист2!BH$1))) -> 168.26923 | AE12: =SUM(T12:AD12) -> 3536.7308 | AF12: =AE12*4.2 -> 14854.269 | AG12: =AF12*2 -> 29708.538 | AH12: =IF(IF(G12="Москва",1,0)=1,Лист2!$BK$6,Лист2!$BL$6) -> 9230 | AI12: =AH12-AF12 -> -5624.2692 | AJ12: =(H12-AE12)*4.2 -> 6145.7308
A13: 1996121848 | B13: Муж | C13: 20 | D13: medium | E13: Да | F13: 60000 | G13: Москва | H13: 7000 | I13: Да | J13: Да | K13: Да | L13: Да | M13: Нет | N13: Да | O13: Нет | P13: Нет | Q13: Да | R13: Нет | S13: Нет | T13: =IF($G13="Москва",1.3*(IF(IF(I13="Да",1,0)=1,1.4*Лист2!AX$1,Лист2!AX$1)),(IF(IF(I13="Да",1,0)=1,1.4*Лист2!AX$1,Лист2!AX$1))) -> 396.9 | U13: =IF($G13="Москва",1.3*(IF(IF(J13="Да",1,0)=1,1.4*Лист2!AY$1,Лист2!AY$1)),(IF(IF(J13="Да",1,0)=1,1.4*Лист2!AY$1,Лист2!AY$1))) -> 350 | V13: =IF($G13="Москва",1.3*(IF(IF(K13="Да",1,0)=1,1.4*Лист2!AZ$1,Лист2!AZ$1)),(IF(IF(K13="Да",1,0)=1,1.4*Лист2!AZ$1,Лист2!AZ$1))) -> 1197 | W13: =IF($G13="Москва",1.3*(IF(IF(L13="Да",1,0)=1,1.4*Лист2!BA$1,Лист2!BA$1)),(IF(IF(L13="Да",1,0)=1,1.4*Лист2!BA$1,Лист2!BA$1))) -> 420 | X13: =IF($G13="Москва",1.3*(IF(IF(M13="Да",1,0)=1,1.4*Лист2!BB$1,Лист2!BB$1)),(IF(IF(M13="Да",1,0)=1,1.4*Лист2!BB$1,Лист2!BB$1))) -> 46 | Y13: =IF($G13="Москва",1.3*(IF(IF(N13="Да",1,0)=1,1.4*Лист2!BC$1,Лист2!BC$1)),(IF(IF(N13="Да",1,0)=1,1.4*Лист2!BC$1,Лист2!BC$1))) -> 1218 | Z13: =IF($G13="Москва",1.3*(IF(IF(O13="Да",1,0)=1,1.4*Лист2!BD$1,Лист2!BD$1)),(IF(IF(O13="Да",1,0)=1,1.4*Лист2!BD$1,Лист2!BD$1))) -> 315 | AA13: =IF($G13="Москва",1.3*(IF(IF(P13="Да",1,0)=1,1.4*Лист2!BE$1,Лист2!BE$1)),(IF(IF(P13="Да",1,0)=1,1.4*Лист2!BE$1,Лист2!BE$1))) -> 725 | ... AD13: =IF($G13="Москва",1.3*(IF(IF(S13="Да",1,0)=1,1.4*Лист2!BH$1,Лист2!BH$1)),(IF(IF(S13="Да",1,0)=1,1.4*Лист2!BH$1,Лист2!BH$1))) -> 156.25 | AE13: =SUM(T13:AD13) -> 4950.85 | AF13: =AE13*4.2 -> 20793.57 | AG13: =AF13*2 -> 41587.14 | AH13: =IF(IF(G13="Москва",1,0)=1,Лист2!$BK$6,Лист2!$BL$6) -> 13651 | AI13: =AH13-AF13 -> -7142.57 | AJ13: =(H13-AE13)*4.2 -> 8606.43
... A24: 1996305312 | B24: Жен | C24: 20 | D24: active | E24: Нет | F24: 60000 | G24: Москва | H24: 4000 | I24: Да | J24: Нет | K24: Да | L24: Нет | M24: Нет | N24: Да | O24: Нет | P24: Нет | Q24: Нет | R24: Нет | S24: Да | T24: =IF($G24="Москва",1.3*(IF(IF(I24="Да",1,0)=1,1.4*Лист2!AX$1,Лист2!AX$1)),(IF(IF(I24="Да",1,0)=1,1.4*Лист2!AX$1,Лист2!AX$1))) -> 396.9 | U24: =IF($G24="Москва",1.3*(IF(IF(J24="Да",1,0)=1,1.4*Лист2!AY$1,Лист2!AY$1)),(IF(IF(J24="Да",1,0)=1,1.4*Лист2!AY$1,Лист2!AY$1))) -> 250 | V24: =IF($G24="Москва",1.3*(IF(IF(K24="Да",1,0)=1,1.4*Лист2!AZ$1,Лист2!AZ$1)),(IF(IF(K24="Да",1,0)=1,1.4*Лист2!AZ$1,Лист2!AZ$1))) -> 1197 | W24: =IF($G24="Москва",1.3*(IF(IF(L24="Да",1,0)=1,1.4*Лист2!BA$1,Лист2!BA$1)),(IF(IF(L24="Да",1,0)=1,1.4*Лист2!BA$1,Лист2!BA$1))) -> 300 | X24: =IF($G24="Москва",1.3*(IF(IF(M24="Да",1,0)=1,1.4*Лист2!BB$1,Лист2!BB$1)),(IF(IF(M24="Да",1,0)=1,1.4*Лист2!BB$1,Лист2!BB$1))) -> 46 | Y24: =IF($G24="Москва",1.3*(IF(IF(N24="Да",1,0)=1,1.4*Лист2!BC$1,Лист2!BC$1)),(IF(IF(N24="Да",1,0)=1,1.4*Лист2!BC$1,Лист2!BC$1))) -> 1218 | Z24: =IF($G24="Москва",1.3*(IF(IF(O24="Да",1,0)=1,1.4*Лист2!BD$1,Лист2!BD$1)),(IF(IF(O24="Да",1,0)=1,1.4*Лист2!BD$1,Лист2!BD$1))) -> 315 | AA24: =IF($G24="Москва",1.3*(IF(IF(P24="Да",1,0)=1,1.4*Лист2!BE$1,Лист2!BE$1)),(IF(IF(P24="Да",1,0)=1,1.4*Лист2!BE$1,Лист2!BE$1))) -> 725 | ... AD24: =IF($G24="Москва",1.3*(IF(IF(S24="Да",1,0)=1,1.4*Лист2!BH$1,Лист2!BH$1)),(IF(IF(S24="Да",1,0)=1,1.4*Лист2!BH$1,Лист2!BH$1))) -> 218.75 | AE24: =SUM(T24:AD24) -> 4768.15 | AF24: =AE24*4.2 -> 20026.23 | AG24: =AF24*2 -> 40052.46 | AH24: =IF(IF(G24="Москва",1,0)=1,Лист2!$BK$6,Лист2!$BL$6) -> 13651 | AI24: =AH24-AF24 -> -6375.23 | AJ24: =(H24-AE24)*4.2 -> -3226.23
A25: 1996328039 | B25: Муж | C25: 20 | D25: medium | E25: Да | F25: 60000 | G25: Москва | H25: 5000 | I25: Нет | J25: Нет | K25: Нет | L25: Нет | M25: Нет | N25: Нет | O25: Нет | P25: Да | Q25: Да | R25: Нет | S25: Да | T25: =IF($G25="Москва",1.3*(IF(IF(I25="Да",1,0)=1,1.4*Лист2!AX$1,Лист2!AX$1)),(IF(IF(I25="Да",1,0)=1,1.4*Лист2!AX$1,Лист2!AX$1))) -> 283.5 | U25: =IF($G25="Москва",1.3*(IF(IF(J25="Да",1,0)=1,1.4*Лист2!AY$1,Лист2!AY$1)),(IF(IF(J25="Да",1,0)=1,1.4*Лист2!AY$1,Лист2!AY$1))) -> 250 | V25: =IF($G25="Москва",1.3*(IF(IF(K25="Да",1,0)=1,1.4*Лист2!AZ$1,Лист2!AZ$1)),(IF(IF(K25="Да",1,0)=1,1.4*Лист2!AZ$1,Лист2!AZ$1))) -> 855 | W25: =IF($G25="Москва",1.3*(IF(IF(L25="Да",1,0)=1,1.4*Лист2!BA$1,Лист2!BA$1)),(IF(IF(L25="Да",1,0)=1,1.4*Лист2!BA$1,Лист2!BA$1))) -> 300 | X25: =IF($G25="Москва",1.3*(IF(IF(M25="Да",1,0)=1,1.4*Лист2!BB$1,Лист2!BB$1)),(IF(IF(M25="Да",1,0)=1,1.4*Лист2!BB$1,Лист2!BB$1))) -> 46 | Y25: =IF($G25="Москва",1.3*(IF(IF(N25="Да",1,0)=1,1.4*Лист2!BC$1,Лист2!BC$1)),(IF(IF(N25="Да",1,0)=1,1.4*Лист2!BC$1,Лист2!BC$1))) -> 870 | Z25: =IF($G25="Москва",1.3*(IF(IF(O25="Да",1,0)=1,1.4*Лист2!BD$1,Лист2!BD$1)),(IF(IF(O25="Да",1,0)=1,1.4*Лист2!BD$1,Лист2!BD$1))) -> 315 | AA25: =IF($G25="Москва",1.3*(IF(IF(P25="Да",1,0)=1,1.4*Лист2!BE$1,Лист2!BE$1)),(IF(IF(P25="Да",1,0)=1,1.4*Лист2!BE$1,Лист2!BE$1))) -> 1015 | ... AD25: =IF($G25="Москва",1.3*(IF(IF(S25="Да",1,0)=1,1.4*Лист2!BH$1,Лист2!BH$1)),(IF(IF(S25="Да",1,0)=1,1.4*Лист2!BH$1,Лист2!BH$1))) -> 218.75 | AE25: =SUM(T25:AD25) -> 4279.95 | AF25: =AE25*4.2 -> 17975.79 | AG25: =AF25*2 -> 35951.58 | AH25: =IF(IF(G25="Москва",1,0)=1,Лист2!$BK$6,Лист2!$BL$6) -> 13651 | AI25: =AH25-AF25 -> -4324.79 | AJ25: =(H25-AE25)*4.2 -> 3024.21
A26: 1996328591 | B26: Муж | C26: 20 | D26: active | E26: Да | F26: 30000 | G26: Москва | H26: 10000 | I26: Нет | J26: Нет | K26: Нет | L26: Нет | M26: Нет | N26: Нет | O26: Нет | P26: Нет | Q26: Нет | R26: Нет | S26: Нет | T26: =IF($G26="Москва",1.3*(IF(IF(I26="Да",1,0)=1,1.4*Лист2!AX$1,Лист2!AX$1)),(IF(IF(I26="Да",1,0)=1,1.4*Лист2!AX$1,Лист2!AX$1))) -> 283.5 | U26: =IF($G26="Москва",1.3*(IF(IF(J26="Да",1,0)=1,1.4*Лист2!AY$1,Лист2!AY$1)),(IF(IF(J26="Да",1,0)=1,1.4*Лист2!AY$1,Лист2!AY$1))) -> 250 | V26: =IF($G26="Москва",1.3*(IF(IF(K26="Да",1,0)=1,1.4*Лист2!AZ$1,Лист2!AZ$1)),(IF(IF(K26="Да",1,0)=1,1.4*Лист2!AZ$1,Лист2!AZ$1))) -> 855 | W26: =IF($G26="Москва",1.3*(IF(IF(L26="Да",1,0)=1,1.4*Лист2!BA$1,Лист2!BA$1)),(IF(IF(L26="Да",1,0)=1,1.4*Лист2!BA$1,Лист2!BA$1))) -> 300 | X26: =IF($G26="Москва",1.3*(IF(IF(M26="Да",1,0)=1,1.4*Лист2!BB$1,Лист2!BB$1)),(IF(IF(M26="Да",1,0)=1,1.4*Лист2!BB$1,Лист2!BB$1))) -> 46 | Y26: =IF($G26="Москва",1.3*(IF(IF(N26="Да",1,0)=1,1.4*Лист2!BC$1,Лист2!BC$1)),(IF(IF(N26="Да",1,0)=1,1.4*Лист2!BC$1,Лист2!BC$1))) -> 870 | Z26: =IF($G26="Москва",1.3*(IF(IF(O26="Да",1,0)=1,1.4*Лист2!BD$1,Лист2!BD$1)),(IF(IF(O26="Да",1,0)=1,1.4*Лист2!BD$1,Лист2!BD$1))) -> 315 | AA26: =IF($G26="Москва",1.3*(IF(IF(P26="Да",1,0)=1,1.4*Лист2!BE$1,Лист2!BE$1)),(IF(IF(P26="Да",1,0)=1,1.4*Лист2!BE$1,Лист2!BE$1))) -> 725 | ... AD26: =IF($G26="Москва",1.3*(IF(IF(S26="Да",1,0)=1,1.4*Лист2!BH$1,Лист2!BH$1)),(IF(IF(S26="Да",1,0)=1,1.4*Лист2!BH$1,Лист2!BH$1))) -> 156.25 | AE26: =SUM(T26:AD26) -> 3902.25 | AF26: =AE26*4.2 -> 16389.45 | AG26: =AF26*2 -> 32778.9 | AH26: =IF(IF(G26="Москва",1,0)=1,Лист2!$BK$6,Лист2!$BL$6) -> 13651 | AI26: =AH26-AF26 -> -2738.45 | AJ26: =(H26-AE26)*4.2 -> 25610.55
A27: 1996330348 | B27: Жен | C27: 20 | D27: active | E27: Да | F27: 60000 | G27: Москва | H27: 7000 | I27: Да | J27: Нет | K27: Нет | L27: Да | M27: Нет | N27: Да | O27: Нет | P27: Нет | Q27: Да | R27: Нет | S27: Да | T27: =IF($G27="Москва",1.3*(IF(IF(I27="Да",1,0)=1,1.4*Лист2!AX$1,Лист2!AX$1)),(IF(IF(I27="Да",1,0)=1,1.4*Лист2!AX$1,Лист2!AX$1))) -> 396.9 | U27: =IF($G27="Москва",1.3*(IF(IF(J27="Да",1,0)=1,1.4*Лист2!AY$1,Лист2!AY$1)),(IF(IF(J27="Да",1,0)=1,1.4*Лист2!AY$1,Лист2!AY$1))) -> 250 | V27: =IF($G27="Москва",1.3*(IF(IF(K27="Да",1,0)=1,1.4*Лист2!AZ$1,Лист2!AZ$1)),(IF(IF(K27="Да",1,0)=1,1.4*Лист2!AZ$1,Лист2!AZ$1))) -> 855 | W27: =IF($G27="Москва",1.3*(IF(IF(L27="Да",1,0)=1,1.4*Лист2!BA$1,Лист2!BA$1)),(IF(IF(L27="Да",1,0)=1,1.4*Лист2!BA$1,Лист2!BA$1))) -> 420 | X27: =IF($G27="Москва",1.3*(IF(IF(M27="Да",1,0)=1,1.4*Лист2!BB$1,Лист2!BB$1)),(IF(IF(M27="Да",1,0)=1,1.4*Лист2!BB$1,Лист2!BB$1))) -> 46 | Y27: =IF($G27="Москва",1.3*(IF(IF(N27="Да",1,0)=1,1.4*Лист2!BC$1,Лист2!BC$1)),(IF(IF(N27="Да",1,0)=1,1.4*Лист2!BC$1,Лист2!BC$1))) -> 1218 | Z27: =IF($G27="Москва",1.3*(IF(IF(O27="Да",1,0)=1,1.4*Лист2!BD$1,Лист2!BD$1)),(IF(IF(O27="Да",1,0)=1,1.4*Лист2!BD$1,Лист2!BD$1))) -> 315 | AA27: =IF($G27="Москва",1.3*(IF(IF(P27="Да",1,0)=1,1.4*Лист2!BE$1,Лист2!BE$1)),(IF(IF(P27="Да",1,0)=1,1.4*Лист2!BE$1,Лист2!BE$1))) -> 725 | ... AD27: =IF($G27="Москва",1.3*(IF(IF(S27="Да",1,0)=1,1.4*Лист2!BH$1,Лист2!BH$1)),(IF(IF(S27="Да",1,0)=1,1.4*Лист2!BH$1,Лист2!BH$1))) -> 218.75 | AE27: =SUM(T27:AD27) -> 4571.35 | AF27: =AE27*4.2 -> 19199.67 | AG27: =AF27*2 -> 38399.34 | AH27: =IF(IF(G27="Москва",1,0)=1,Лист2!$BK$6,Лист2!$BL$6) -> 13651 | AI27: =AH27-AF27 -> -5548.67 | AJ27: =(H27-AE27)*4.2 -> 10200.33
A28: 1996330598 | B28: Жен | C28: 20 | D28: medium | E28: Да | F28: 60000 | G28: Москва | H28: 15000 | I28: Нет | J28: Нет | K28: Нет | L28: Да | M28: Нет | N28: Да | O28: Да | P28: Нет | Q28: Да | R28: Да | S28: Нет | T28: =IF($G28="Москва",1.3*(IF(IF(I28="Да",1,0)=1,1.4*Лист2!AX$1,Лист2!AX$1)),(IF(IF(I28="Да",1,0)=1,1.4*Лист2!AX$1,Лист2!AX$1))) -> 283.5 | U28: =IF($G28="Москва",1.3*(IF(IF(J28="Да",1,0)=1,1.4*Лист2!AY$1,Лист2!AY$1)),(IF(IF(J28="Да",1,0)=1,1.4*Лист2!AY$1,Лист2!AY$1))) -> 250 | V28: =IF($G28="Москва",1.3*(IF(IF(K28="Да",1,0)=1,1.4*Лист2!AZ$1,Лист2!AZ$1)),(IF(IF(K28="Да",1,0)=1,1.4*Лист2!AZ$1,Лист2!AZ$1))) -> 855 | W28: =IF($G28="Москва",1.3*(IF(IF(L28="Да",1,0)=1,1.4*Лист2!BA$1,Лист2!BA$1)),(IF(IF(L28="Да",1,0)=1,1.4*Лист2!BA$1,Лист2!BA$1))) -> 420 | X28: =IF($G28="Москва",1.3*(IF(IF(M28="Да",1,0)=1,1.4*Лист2!BB$1,Лист2!BB$1)),(IF(IF(M28="Да",1,0)=1,1.4*Лист2!BB$1,Лист2!BB$1))) -> 46 | Y28: =IF($G28="Москва",1.3*(IF(IF(N28="Да",1,0)=1,1.4*Лист2!BC$1,Лист2!BC$1)),(IF(IF(N28="Да",1,0)=1,1.4*Лист2!BC$1,Лист2!BC$1))) -> 1218 | Z28: =IF($G28="Москва",1.3*(IF(IF(O28="Да",1,0)=1,1.4*Лист2!BD$1,Лист2!BD$1)),(IF(IF(O28="Да",1,0)=1,1.4*Лист2!BD$1,Лист2!BD$1))) -> 441 | AA28: =IF($G28="Москва",1.3*(IF(IF(P28="Да",1,0)=1,1.4*Лист2!BE$1,Лист2!BE$1)),(IF(IF(P28="Да",1,0)=1,1.4*Лист2!BE$1,Лист2!BE$1))) -> 725 | ... AD28: =IF($G28="Москва",1.3*(IF(IF(S28="Да",1,0)=1,1.4*Лист2!BH$1,Лист2!BH$1)),(IF(IF(S28="Да",1,0)=1,1.4*Лист2!BH$1,Лист2!BH$1))) -> 156.25 | AE28: =SUM(T28:AD28) -> 4536.85 | AF28: =AE28*4.2 -> 19054.77 | AG28: =AF28*2 -> 38109.54 | AH28: =IF(IF(G28="Москва",1,0)=1,Лист2!$BK$6,Лист2!$BL$6) -> 13651 | AI28: =AH28-AF28 -> -5403.77 | AJ28: =(H28-AE28)*4.2 -> 43945.23
A29: 1996331297 | B29: Муж | C29: 20 | D29: medium | E29: Нет | F29: 12000 | G29: Москва | H29: 20000 | I29: Нет | J29: Нет | K29: Да | L29: Нет | M29: Нет | N29: Да | O29: Нет | P29: Да | Q29: Да | R29: Нет | S29: Нет | T29: =IF($G29="Москва",1.3*(IF(IF(I29="Да",1,0)=1,1.4*Лист2!AX$1,Лист2!AX$1)),(IF(IF(I29="Да",1,0)=1,1.4*Лист2!AX$1,Лист2!AX$1))) -> 283.5 | U29: =IF($G29="Москва",1.3*(IF(IF(J29="Да",1,0)=1,1.4*Лист2!AY$1,Лист2!AY$1)),(IF(IF(J29="Да",1,0)=1,1.4*Лист2!AY$1,Лист2!AY$1))) -> 250 | V29: =IF($G29="Москва",1.3*(IF(IF(K29="Да",1,0)=1,1.4*Лист2!AZ$1,Лист2!AZ$1)),(IF(IF(K29="Да",1,0)=1,1.4*Лист2!AZ$1,Лист2!AZ$1))) -> 1197 | W29: =IF($G29="Москва",1.3*(IF(IF(L29="Да",1,0)=1,1.4*Лист2!BA$1,Лист2!BA$1)),(IF(IF(L29="Да",1,0)=1,1.4*Лист2!BA$1,Лист2!BA$1))) -> 300 | X29: =IF($G29="Москва",1.3*(IF(IF(M29="Да",1,0)=1,1.4*Лист2!BB$1,Лист2!BB$1)),(IF(IF(M29="Да",1,0)=1,1.4*Лист2!BB$1,Лист2!BB$1))) -> 46 | Y29: =IF($G29="Москва",1.3*(IF(IF(N29="Да",1,0)=1,1.4*Лист2!BC$1,Лист2!BC$1)),(IF(IF(N29="Да",1,0)=1,1.4*Лист2!BC$1,Лист2!BC$1))) -> 1218 | Z29: =IF($G29="Москва",1.3*(IF(IF(O29="Да",1,0)=1,1.4*Лист2!BD$1,Лист2!BD$1)),(IF(IF(O29="Да",1,0)=1,1.4*Лист2!BD$1,Лист2!BD$1))) -> 315 | AA29: =IF($G29="Москва",1.3*(IF(IF(P29="Да",1,0)=1,1.4*Лист2!BE$1,Лист2!BE$1)),(IF(IF(P29="Да",1,0)=1,1.4*Лист2!BE$1,Лист2!BE$1))) -> 1015 | ... AD29: =IF($G29="Москва",1.3*(IF(IF(S29="Да",1,0)=1,1.4*Лист2!BH$1,Лист2!BH$1)),(IF(IF(S29="Да",1,0)=1,1.4*Лист2!BH$1,Лист2!BH$1))) -> 156.25 | AE29: =SUM(T29:AD29) -> 4907.45 | AF29: =AE29*4.2 -> 20611.29 | AG29: =AF29*2 -> 41222.58 | AH29: =IF(IF(G29="Москва",1,0)=1,Лист2!$BK$6,Лист2!$BL$6) -> 13651 | AI29: =AH29-AF29 -> -6960.29 | AJ29: =(H29-AE29)*4.2 -> 63388.71
A30: 1996352201 | B30: Муж | C30: 20 | D30: passive | E30: Нет | F30: 12000 | G30: Волжский, Волгоградская область | H30: 20000 | I30: Нет | J30: Да | K30: Нет | L30: Да | M30: Нет | N30: Да | O30: Нет | P30: Да | Q30: Да | R30: Да | S30: Нет | T30: =IF($G30="Москва",1.3*(IF(IF(I30="Да",1,0)=1,1.4*Лист2!AX$1,Лист2!AX$1)),(IF(IF(I30="Да",1,0)=1,1.4*Лист2!AX$1,Лист2!AX$1))) -> 218.07692 | U30: =IF($G30="Москва",1.3*(IF(IF(J30="Да",1,0)=1,1.4*Лист2!AY$1,Лист2!AY$1)),(IF(IF(J30="Да",1,0)=1,1.4*Лист2!AY$1,Лист2!AY$1))) -> 269.23077 | V30: =IF($G30="Москва",1.3*(IF(IF(K30="Да",1,0)=1,1.4*Лист2!AZ$1,Лист2!AZ$1)),(IF(IF(K30="Да",1,0)=1,1.4*Лист2!AZ$1,Лист2!AZ$1))) -> 657.69231 | W30: =IF($G30="Москва",1.3*(IF(IF(L30="Да",1,0)=1,1.4*Лист2!BA$1,Лист2!BA$1)),(IF(IF(L30="Да",1,0)=1,1.4*Лист2!BA$1,Лист2!BA$1))) -> 323.07692 | X30: =IF($G30="Москва",1.3*(IF(IF(M30="Да",1,0)=1,1.4*Лист2!BB$1,Лист2!BB$1)),(IF(IF(M30="Да",1,0)=1,1.4*Лист2!BB$1,Лист2!BB$1))) -> 35.384615 | Y30: =IF($G30="Москва",1.3*(IF(IF(N30="Да",1,0)=1,1.4*Лист2!BC$1,Лист2!BC$1)),(IF(IF(N30="Да",1,0)=1,1.4*Лист2!BC$1,Лист2!BC$1))) -> 936.92308 | Z30: =IF($G30="Москва",1.3*(IF(IF(O30="Да",1,0)=1,1.4*Лист2!BD$1,Лист2!BD$1)),(IF(IF(O30="Да",1,0)=1,1.4*Лист2!BD$1,Лист2!BD$1))) -> 242.30769 | AA30: =IF($G30="Москва",1.3*(IF(IF(P30="Да",1,0)=1,1.4*Лист2!BE$1,Лист2!BE$1)),(IF(IF(P30="Да",1,0)=1,1.4*Лист2!BE$1,Лист2!BE$1))) -> 780.76923 | ... AD30: =IF($G30="Москва",1.3*(IF(IF(S30="Да",1,0)=1,1.4*Лист2!BH$1,Лист2!BH$1)),(IF(IF(S30="Да",1,0)=1,1.4*Лист2!BH$1,Лист2!BH$1))) -> 120.19231 | AE30: =SUM(T30:AD30) -> 3692.9615 | AF30: =AE30*4.2 -> 15510.438 | AG30: =AF30*2 -> 31020.877 | AH30: =IF(IF(G30="Москва",1,0)=1,Лист2!$BK$6,Лист2!$BL$6) -> 9230 | AI30: =AH30-AF30 -> -6280.4385 | AJ30: =(H30-AE30)*4.2 -> 68489.562
A31: 1996357490 | B31: Муж | C31: 20 | D31: medium | E31: Да | F31: 60000 | G31: Москва | H31: 1000 | I31: Нет | J31: Нет | K31: Нет | L31: Да | M31: Нет | N31: Нет | O31: Нет | P31: Да | Q31: Да | R31: Нет | S31: Нет | T31: =IF($G31="Москва",1.3*(IF(IF(I31="Да",1,0)=1,1.4*Лист2!AX$1,Лист2!AX$1)),(IF(IF(I31="Да",1,0)=1,1.4*Лист2!AX$1,Лист2!AX$1))) -> 283.5 | U31: =IF($G31="Москва",1.3*(IF(IF(J31="Да",1,0)=1,1.4*Лист2!AY$1,Лист2!AY$1)),(IF(IF(J31="Да",1,0)=1,1.4*Лист2!AY$1,Лист2!AY$1))) -> 250 | V31: =IF($G31="Москва",1.3*(IF(IF(K31="Да",1,0)=1,1.4*Лист2!AZ$1,Лист2!AZ$1)),(IF(IF(K31="Да",1,0)=1,1.4*Лист2!AZ$1,Лист2!AZ$1))) -> 855 | W31: =IF($G31="Москва",1.3*(IF(IF(L31="Да",1,0)=1,1.4*Лист2!BA$1,Лист2!BA$1)),(IF(IF(L31="Да",1,0)=1,1.4*Лист2!BA$1,Лист2!BA$1))) -> 420 | X31: =IF($G31="Москва",1.3*(IF(IF(M31="Да",1,0)=1,1.4*Лист2!BB$1,Лист2!BB$1)),(IF(IF(M31="Да",1,0)=1,1.4*Лист2!BB$1,Лист2!BB$1))) -> 46 | Y31: =IF($G31="Москва",1.3*(IF(IF(N31="Да",1,0)=1,1.4*Лист2!BC$1,Лист2!BC$1)),(IF(IF(N31="Да",1,0)=1,1.4*Лист2!BC$1,Лист2!BC$1))) -> 870 | Z31: =IF($G31="Москва",1.3*(IF(IF(O31="Да",1,0)=1,1.4*Лист2!BD$1,Лист2!BD$1)),(IF(IF(O31="Да",1,0)=1,1.4*Лист2!BD$1,Лист2!BD$1))) -> 315 | AA31: =IF($G31="Москва",1.3*(IF(IF(P31="Да",1,0)=1,1.4*Лист2!BE$1,Лист2!BE$1)),(IF(IF(P31="Да",1,0)=1,1.4*Лист2!BE$1,Лист2!BE$1))) -> 1015 | ... AD31: =IF($G31="Москва",1.3*(IF(IF(S31="Да",1,0)=1,1.4*Лист2!BH$1,Лист2!BH$1)),(IF(IF(S31="Да",1,0)=1,1.4*Лист2!BH$1,Лист2!BH$1))) -> 156.25 | AE31: =SUM(T31:AD31) -> 4337.45 | AF31: =AE31*4.2 -> 18217.29 | AG31: =AF31*2 -> 36434.58 | AH31: =IF(IF(G31="Москва",1,0)=1,Лист2!$BK$6,Лист2!$BL$6) -> 13651 | AI31: =AH31-AF31 -> -4566.29 | AJ31: =(H31-AE31)*4.2 -> -14017.29
A32: 1996382686 | B32: Муж | C32: 20 | D32: medium | E32: Нет | F32: 12000 | G32: Щёлково, Москва и Московская область | H32: 2777 | I32: Да | J32: Нет | K32: Нет | L32: Нет | M32: Да | N32: Да | O32: Нет | P32: Нет | Q32: Да | R32: Да | S32: Да | T32: =IF($G32="Москва",1.3*(IF(IF(I32="Да",1,0)=1,1.4*Лист2!AX$1,Лист2!AX$1)),(IF(IF(I32="Да",1,0)=1,1.4*Лист2!AX$1,Лист2!AX$1))) -> 305.30769 | U32: =IF($G32="Москва",1.3*(IF(IF(J32="Да",1,0)=1,1.4*Лист2!AY$1,Лист2!AY$1)),(IF(IF(J32="Да",1,0)=1,1.4*Лист2!AY$1,Лист2!AY$1))) -> 192.30769 | V32: =IF($G32="Москва",1.3*(IF(IF(K32="Да",1,0)=1,1.4*Лист2!AZ$1,Лист2!AZ$1)),(IF(IF(K32="Да",1,0)=1,1.4*Лист2!AZ$1,Лист2!AZ$1))) -> 657.69231 | W32: =IF($G32="Москва",1.3*(IF(IF(L32="Да",1,0)=1,1.4*Лист2!BA$1,Лист2!BA$1)),(IF(IF(L32="Да",1,0)=1,1.4*Лист2!BA$1,Лист2!BA$1))) -> 230.76923 | X32: =IF($G32="Москва",1.3*(IF(IF(M32="Да",1,0)=1,1.4*Лист2!BB$1,Лист2!BB$1)),(IF(IF(M32="Да",1,0)=1,1.4*Лист2!BB$1,Лист2!BB$1))) -> 49.538462 | Y32: =IF($G32="Москва",1.3*(IF(IF(N32="Да",1,0)=1,1.4*Лист2!BC$1,Лист2!BC$1)),(IF(IF(N32="Да",1,0)=1,1.4*Лист2!BC$1,Лист2!BC$1))) -> 936.92308 | Z32: =IF($G32="Москва",1.3*(IF(IF(O32="Да",1,0)=1,1.4*Лист2!BD$1,Лист2!BD$1)),(IF(IF(O32="Да",1,0)=1,1.4*Лист2!BD$1,Лист2!BD$1))) -> 242.30769 | AA32: =IF($G32="Москва",1.3*(IF(IF(P32="Да",1,0)=1,1.4*Лист2!BE$1,Лист2!BE$1)),(IF(IF(P32="Да",1,0)=1,1.4*Лист2!BE$1,Лист2!BE$1))) -> 557.69231 | ... AD32: =IF($G32="Москва",1.3*(IF(IF(S32="Да",1,0)=1,1.4*Лист2!BH$1,Лист2!BH$1)),(IF(IF(S32="Да",1,0)=1,1.4*Лист2!BH$1,Лист2!BH$1))) -> 168.26923 | AE32: =SUM(T32:AD32) -> 3450.1154 | AF32: =AE32*4.2 -> 14490.485 | AG32: =AF32*2 -> 28980.969 | AH32: =IF(IF(G32="Москва",1,0)=1,Лист2!$BK$6,Лист2!$BL$6) -> 9230 | AI32: =AH32-AF32 -> -5260.4846 | AJ32: =(H32-AE32)*4.2 -> -2827.0846
A33: 1996462484 | B33: Жен | C33: 35 | D33: active | E33: Да | F33: 60000 | G33: Улан-Удэ, Республика Бурятия | H33: 20000 | I33: Нет | J33: Нет | K33: Да | L33: Да | M33: Нет | N33: Да | O33: Нет | P33: Нет | Q33: Да | R33: Нет | S33: Нет | T33: =IF($G33="Москва",1.3*(IF(IF(I33="Да",1,0)=1,1.4*Лист2!AX$1,Лист2!AX$1)),(IF(IF(I33="Да",1,0)=1,1.4*Лист2!AX$1,Лист2!AX$1))) -> 218.07692 | U33: =IF($G33="Москва",1.3*(IF(IF(J33="Да",1,0)=1,1.4*Лист2!AY$1,Лист2!AY$1)),(IF(IF(J33="Да",1,0)=1,1.4*Лист2!AY$1,Лист2!AY$1))) -> 192.30769 | V33: =IF($G33="Москва",1.3*(IF(IF(K33="Да",1,0)=1,1.4*Лист2!AZ$1,Лист2!AZ$1)),(IF(IF(K33="Да",1,0)=1,1.4*Лист2!AZ$1,Лист2!AZ$1))) -> 920.76923 | W33: =IF($G33="Москва",1.3*(IF(IF(L33="Да",1,0)=1,1.4*Лист2!BA$1,Лист2!BA$1)),(IF(IF(L33="Да",1,0)=1,1.4*Лист2!BA$1,Лист2!BA$1))) -> 323.07692 | X33: =IF($G33="Москва",1.3*(IF(IF(M33="Да",1,0)=1,1.4*Лист2!BB$1,Лист2!BB$1)),(IF(IF(M33="Да",1,0)=1,1.4*Лист2!BB$1,Лист2!BB$1))) -> 35.384615 | Y33: =IF($G33="Москва",1.3*(IF(IF(N33="Да",1,0)=1,1.4*Лист2!BC$1,Лист2!BC$1)),(IF(IF(N33="Да",1,0)=1,1.4*Лист2!BC$1,Лист2!BC$1))) -> 936.92308 | Z33: =IF($G33="Москва",1.3*(IF(IF(O33="Да",1,0)=1,1.4*Лист2!BD$1,Лист2!BD$1)),(IF(IF(O33="Да",1,0)=1,1.4*Лист2!BD$1,Лист2!BD$1))) -> 242.30769 | AA33: =IF($G33="Москва",1.3*(IF(IF(P33="Да",1,0)=1,1.4*Лист2!BE$1,Лист2!BE$1)),(IF(IF(P33="Да",1,0)=1,1.4*Лист2!BE$1,Лист2!BE$1))) -> 557.69231 | ... AD33: =IF($G33="Москва",1.3*(IF(IF(S33="Да",1,0)=1,1.4*Лист2!BH$1,Лист2!BH$1)),(IF(IF(S33="Да",1,0)=1,1.4*Лист2!BH$1,Лист2!BH$1))) -> 120.19231 | AE33: =SUM(T33:AD33) -> 3644.1923 | AF33: =AE33*4.2 -> 15305.608 | AG33: =AF33*2 -> 30611.215 | AH33: =IF(IF(G33="Москва",1,0)=1,Лист2!$BK$6,Лист2!$BL$6) -> 9230 | AI33: =AH33-AF33 -> -6075.6077 | AJ33: =(H33-AE33)*4.2 -> 68694.392
A34: 1996671051 | B34: Жен | C34: 20 | D34: medium | E34: Да | F34: 30000 | G34: Тула, Тульская область | H34: 5000 | I34: Нет | J34: Нет | K34: Да | L34: Да | M34: Нет | N34: Да | O34: Да | P34: Нет | Q34: Да | R34: Да | S34: Да | T34: =IF($G34="Москва",1.3*(IF(IF(I34="Да",1,0)=1,1.4*Лист2!AX$1,Лист2!AX$1)),(IF(IF(I34="Да",1,0)=1,1.4*Лист2!AX$1,Лист2!AX$1))) -> 218.07692 | U34: =IF($G34="Москва",1.3*(IF(IF(J34="Да",1,0)=1,1.4*Лист2!AY$1,Лист2!AY$1)),(IF(IF(J34="Да",1,0)=1,1.4*Лист2!AY$1,Лист2!AY$1))) -> 192.30769 | V34: =IF($G34="Москва",1.3*(IF(IF(K34="Да",1,0)=1,1.4*Лист2!AZ$1,Лист2!AZ$1)),(IF(IF(K34="Да",1,0)=1,1.4*Лист2!AZ$1,Лист2!AZ$1))) -> 920.76923 | W34: =IF($G34="Москва",1.3*(IF(IF(L34="Да",1,0)=1,1.4*Лист2!BA$1,Лист2!BA$1)),(IF(IF(L34="Да",1,0)=1,1.4*Лист2!BA$1,Лист2!BA$1))) -> 323.07692 | X34: =IF($G34="Москва",1.3*(IF(IF(M34="Да",1,0)=1,1.4*Лист2!BB$1,Лист2!BB$1)),(IF(IF(M34="Да",1,0)=1,1.4*Лист2!BB$1,Лист2!BB$1))) -> 35.384615 | Y34: =IF($G34="Москва",1.3*(IF(IF(N34="Да",1,0)=1,1.4*Лист2!BC$1,Лист2!BC$1)),(IF(IF(N34="Да",1,0)=1,1.4*Лист2!BC$1,Лист2!BC$1))) -> 936.92308 | Z34: =IF($G34="Москва",1.3*(IF(IF(O34="Да",1,0)=1,1.4*Лист2!BD$1,Лист2!BD$1)),(IF(IF(O34="Да",1,0)=1,1.4*Лист2!BD$1,Лист2!BD$1))) -> 339.23077 | AA34: =IF($G34="Москва",1.3*(IF(IF(P34="Да",1,0)=1,1.4*Лист2!BE$1,Лист2!BE$1)),(IF(IF(P34="Да",1,0)=1,1.4*Лист2!BE$1,Лист2!BE$1))) -> 557.69231 | ... AD34: =IF($G34="Москва",1.3*(IF(IF(S34="Да",1,0)=1,1.4*Лист2!BH$1,Лист2!BH$1)),(IF(IF(S34="Да",1,0)=1,1.4*Лист2!BH$1,Лист2!BH$1))) -> 168.26923 | AE34: =SUM(T34:AD34) -> 3801.0385 | AF34: =AE34*4.2 -> 15964.362 | AG34: =AF34*2 -> 31928.723 | AH34: =IF(IF(G34="Москва",1,0)=1,Лист2!$BK$6,Лист2!$BL$6) -> 9230 | AI34: =AH34-AF34 -> -6734.3615 | AJ34: =(H34-AE34)*4.2 -> 5035.6385
A35: 1997094996 | B35: Жен | C35: 20 | D35: active | E35: Да | F35: 60000 | G35: Волжский, Волгоградская область | H35: 5000 | I35: Нет | J35: Нет | K35: Да | L35: Да | M35: Нет | N35: Да | O35: Да | P35: Да | Q35: Да | R35: Нет | S35: Нет | T35: =IF($G35="Москва",1.3*(IF(IF(I35="Да",1,0)=1,1.4*Лист2!AX$1,Лист2!AX$1)),(IF(IF(I35="Да",1,0)=1,1.4*Лист2!AX$1,Лист2!AX$1))) -> 218.07692 | U35: =IF($G35="Москва",1.3*(IF(IF(J35="Да",1,0)=1,1.4*Лист2!AY$1,Лист2!AY$1)),(IF(IF(J35="Да",1,0)=1,1.4*Лист2!AY$1,Лист2!AY$1))) -> 192.30769 | V35: =IF($G35="Москва",1.3*(IF(IF(K35="Да",1,0)=1,1.4*Лист2!AZ$1,Лист2!AZ$1)),(IF(IF(K35="Да",1,0)=1,1.4*Лист2!AZ$1,Лист2!AZ$1))) -> 920.76923 | W35: =IF($G35="Москва",1.3*(IF(IF(L35="Да",1,0)=1,1.4*Лист2!BA$1,Лист2!BA$1)),(IF(IF(L35="Да",1,0)=1,1.4*Лист2!BA$1,Лист2!BA$1))) -> 323.07692 | X35: =IF($G35="Москва",1.3*(IF(IF(M35="Да",1,0)=1,1.4*Лист2!BB$1,Лист2!BB$1)),(IF(IF(M35="Да",1,0)=1,1.4*Лист2!BB$1,Лист2!BB$1))) -> 35.384615 | Y35: =IF($G35="Москва",1.3*(IF(IF(N35="Да",1,0)=1,1.4*Лист2!BC$1,Лист2!BC$1)),(IF(IF(N35="Да",1,0)=1,1.4*Лист2!BC$1,Лист2!BC$1))) -> 936.92308 | Z35: =IF($G35="Москва",1.3*(IF(IF(O35="Да",1,0)=1,1.4*Лист2!BD$1,Лист2!BD$1)),(IF(IF(O35="Да",1,0)=1,1.4*Лист2!BD$1,Лист2!BD$1))) -> 339.23077 | AA35: =IF($G35="Москва",1.3*(IF(IF(P35="Да",1,0)=1,1.4*Лист2!BE$1,Лист2!BE$1)),(IF(IF(P35="Да",1,0)=1,1.4*Лист2!BE$1,Лист2!BE$1))) -> 780.76923 | ... AD35: =IF($G35="Москва",1.3*(IF(IF(S35="Да",1,0)=1,1.4*Лист2!BH$1,Лист2!BH$1)),(IF(IF(S35="Да",1,0)=1,1.4*Лист2!BH$1,Лист2!BH$1))) -> 120.19231 | AE35: =SUM(T35:AD35) -> 3964.1923 | AF35: =AE35*4.2 -> 16649.608 | AG35: =AF35*2 -> 33299.215 | AH35: =IF(IF(G35="Москва",1,0)=1,Лист2!$BK$6,Лист2!$BL$6) -> 9230 | AI35: =AH35-AF35 -> -7419.6077 | AJ35: =(H35-AE35)*4.2 -> 4350.3923
A36: 1997394046 | B36: Жен | C36: 20 | D36: active | E36: Да | F36: 12000 | G36: Волжский, Волгоградская область | H36: 10000 | I36: Нет | J36: Нет | K36: Да | L36: Да | M36: Нет | N36: Да | O36: Да | P36: Да | Q36: Да | R36: Да | S36: Да | T36: =IF($G36="Москва",1.3*(IF(IF(I36="Да",1,0)=1,1.4*Лист2!AX$1,Лист2!AX$1)),(IF(IF(I36="Да",1,0)=1,1.4*Лист2!AX$1,Лист2!AX$1))) -> 218.07692 | U36: =IF($G36="Москва",1.3*(IF(IF(J36="Да",1,0)=1,1.4*Лист2!AY$1,Лист2!AY$1)),(IF(IF(J36="Да",1,0)=1,1.4*Лист2!AY$1,Лист2!AY$1))) -> 192.30769 | V36: =IF($G36="Москва",1.3*(IF(IF(K36="Да",1,0)=1,1.4*Лист2!AZ$1,Лист2!AZ$1)),(IF(IF(K36="Да",1,0)=1,1.4*Лист2!AZ$1,Лист2!AZ$1))) -> 920.76923 | W36: =IF($G36="Москва",1.3*(IF(IF(L36="Да",1,0)=1,1.4*Лист2!BA$1,Лист2!BA$1)),(IF(IF(L36="Да",1,0)=1,1.4*Лист2!BA$1,Лист2!BA$1))) -> 323.07692 | X36: =IF($G36="Москва",1.3*(IF(IF(M36="Да",1,0)=1,1.4*Лист2!BB$1,Лист2!BB$1)),(IF(IF(M36="Да",1,0)=1,1.4*Лист2!BB$1,Лист2!BB$1))) -> 35.384615 | Y36: =IF($G36="Москва",1.3*(IF(IF(N36="Да",1,0)=1,1.4*Лист2!BC$1,Лист2!BC$1)),(IF(IF(N36="Да",1,0)=1,1.4*Лист2!BC$1,Лист2!BC$1))) -> 936.92308 | Z36: =IF($G36="Москва",1.3*(IF(IF(O36="Да",1,0)=1,1.4*Лист2!BD$1,Лист2!BD$1)),(IF(IF(O36="Да",1,0)=1,1.4*Лист2!BD$1,Лист2!BD$1))) -> 339.23077 | AA36: =IF($G36="Москва",1.3*(IF(IF(P36="Да",1,0)=1,1.4*Лист2!BE$1,Лист2!BE$1)),(IF(IF(P36="Да",1,0)=1,1.4*Лист2!BE$1,Лист2!BE$1))) -> 780.76923 | ... AD36: =IF($G36="Москва",1.3*(IF(IF(S36="Да",1,0)=1,1.4*Лист2!BH$1,Лист2!BH$1)),(IF(IF(S36="Да",1,0)=1,1.4*Лист2!BH$1,Лист2!BH$1))) -> 168.26923 | AE36: =SUM(T36:AD36) -> 4024.1154 | AF36: =AE36*4.2 -> 16901.285 | AG36: =AF36*2 -> 33802.569 | AH36: =IF(IF(G36="Москва",1,0)=1,Лист2!$BK$6,Лист2!$BL$6) -> 9230 | AI36: =AH36-AF36 -> -7671.2846 | AJ36: =(H36-AE36)*4.2 -> 25098.715
A37: 1997430362 | B37: Муж | C37: 18 | D37: active | E37: Нет | F37: 12000 | G37: Волжский, Волгоградская область | H37: 4000 | I37: Да | J37: Нет | K37: Нет | L37: Нет | M37: Нет | N37: Да | O37: Нет | P37: Нет | Q37: Да | R37: Да | S37: Да | T37: =IF($G37="Москва",1.3*(IF(IF(I37="Да",1,0)=1,1.4*Лист2!AX$1,Лист2!AX$1)),(IF(IF(I37="Да",1,0)=1,1.4*Лист2!AX$1,Лист2!AX$1))) -> 305.30769 | U37: =IF($G37="Москва",1.3*(IF(IF(J37="Да",1,0)=1,1.4*Лист2!AY$1,Лист2!AY$1)),(IF(IF(J37="Да",1,0)=1,1.4*Лист2!AY$1,Лист2!AY$1))) -> 192.30769 | V37: =IF($G37="Москва",1.3*(IF(IF(K37="Да",1,0)=1,1.4*Лист2!AZ$1,Лист2!AZ$1)),(IF(IF(K37="Да",1,0)=1,1.4*Лист2!AZ$1,Лист2!AZ$1))) -> 657.69231 | W37: =IF($G37="Москва",1.3*(IF(IF(L37="Да",1,0)=1,1.4*Лист2!BA$1,Лист2!BA$1)),(IF(IF(L37="Да",1,0)=1,1.4*Лист2!BA$1,Лист2!BA$1))) -> 230.76923 | X37: =IF($G37="Москва",1.3*(IF(IF(M37="Да",1,0)=1,1.4*Лист2!BB$1,Лист2!BB$1)),(IF(IF(M37="Да",1,0)=1,1.4*Лист2!BB$1,Лист2!BB$1))) -> 35.384615 | Y37: =IF($G37="Москва",1.3*(IF(IF(N37="Да",1,0)=1,1.4*Лист2!BC$1,Лист2!BC$1)),(IF(IF(N37="Да",1,0)=1,1.4*Лист2!BC$1,Лист2!BC$1))) -> 936.92308 | Z37: =IF($G37="Москва",1.3*(IF(IF(O37="Да",1,0)=1,1.4*Лист2!BD$1,Лист2!BD$1)),(IF(IF(O37="Да",1,0)=1,1.4*Лист2!BD$1,Лист2!BD$1))) -> 242.30769 | AA37: =IF($G37="Москва",1.3*(IF(IF(P37="Да",1,0)=1,1.4*Лист2!BE$1,Лист2!BE$1)),(IF(IF(P37="Да",1,0)=1,1.4*Лист2!BE$1,Лист2!BE$1))) -> 557.69231 | ... AD37: =IF($G37="Москва",1.3*(IF(IF(S37="Да",1,0)=1,1.4*Лист2!BH$1,Лист2!BH$1)),(IF(IF(S37="Да",1,0)=1,1.4*Лист2!BH$1,Лист2!BH$1))) -> 168.26923 | AE37: =SUM(T37:AD37) -> 3435.9615 | AF37: =AE37*4.2 -> 14431.038 | AG37: =AF37*2 -> 28862.077 | AH37: =IF(IF(G37="Москва",1,0)=1,Лист2!$BK$6,Лист2!$BL$6) -> 9230 | AI37: =AH37-AF37 -> -5201.0385 | AJ37: =(H37-AE37)*4.2 -> 2368.9615
... A39: 1999577997 | B39: Жен | C39: 50 | D39: active | E39: Да | F39: 60000 | G39: Волжский, Волгоградская область | H39: 5000 | I39: Нет | J39: Да | K39: Да | L39: Нет | M39: Нет | N39: Да | O39: Нет | P39: Нет | Q39: Да | R39: Да | S39: Да | T39: =IF($G39="Москва",1.3*(IF(IF(I39="Да",1,0)=1,1.4*Лист2!AX$1,Лист2!AX$1)),(IF(IF(I39="Да",1,0)=1,1.4*Лист2!AX$1,Лист2!AX$1))) -> 218.07692 | U39: =IF($G39="Москва",1.3*(IF(IF(J39="Да",1,0)=1,1.4*Лист2!AY$1,Лист2!AY$1)),(IF(IF(J39="Да",1,0)=1,1.4*Лист2!AY$1,Лист2!AY$1))) -> 269.23077 | V39: =IF($G39="Москва",1.3*(IF(IF(K39="Да",1,0)=1,1.4*Лист2!AZ$1,Лист2!AZ$1)),(IF(IF(K39="Да",1,0)=1,1.4*Лист2!AZ$1,Лист2!AZ$1))) -> 920.76923 | W39: =IF($G39="Москва",1.3*(IF(IF(L39="Да",1,0)=1,1.4*Лист2!BA$1,Лист2!BA$1)),(IF(IF(L39="Да",1,0)=1,1.4*Лист2!BA$1,Лист2!BA$1))) -> 230.76923 | X39: =IF($G39="Москва",1.3*(IF(IF(M39="Да",1,0)=1,1.4*Лист2!BB$1,Лист2!BB$1)),(IF(IF(M39="Да",1,0)=1,1.4*Лист2!BB$1,Лист2!BB$1))) -> 35.384615 | Y39: =IF($G39="Москва",1.3*(IF(IF(N39="Да",1,0)=1,1.4*Лист2!BC$1,Лист2!BC$1)),(IF(IF(N39="Да",1,0)=1,1.4*Лист2!BC$1,Лист2!BC$1))) -> 936.92308 | Z39: =IF($G39="Москва",1.3*(IF(IF(O39="Да",1,0)=1,1.4*Лист2!BD$1,Лист2!BD$1)),(IF(IF(O39="Да",1,0)=1,1.4*Лист2!BD$1,Лист2!BD$1))) -> 242.30769 | AA39: =IF($G39="Москва",1.3*(IF(IF(P39="Да",1,0)=1,1.4*Лист2!BE$1,Лист2!BE$1)),(IF(IF(P39="Да",1,0)=1,1.4*Лист2!BE$1,Лист2!BE$1))) -> 557.69231 | ... AD39: =IF($G39="Москва",1.3*(IF(IF(S39="Да",1,0)=1,1.4*Лист2!BH$1,Лист2!BH$1)),(IF(IF(S39="Да",1,0)=1,1.4*Лист2!BH$1,Лист2!BH$1))) -> 168.26923 | AE39: =SUM(T39:AD39) -> 3688.7308 | AF39: =AE39*4.2 -> 15492.669 | AG39: =AF39*2 -> 30985.338 | AH39: =IF(IF(G39="Москва",1,0)=1,Лист2!$BK$6,Лист2!$BL$6) -> 9230 | AI39: =AH39-AF39 -> -6262.6692 | AJ39: =(H39-AE39)*4.2 -> 5507.3308
A40: 2009568744 | B40: Жен | C40: 20 | D40: active | E40: Нет | F40: 12000 | G40: Новосибирск, Новосибирская область | H40: 20000 | I40: Да | J40: Нет | K40: Да | L40: Да | M40: Нет | N40: Да | O40: Нет | P40: Да | Q40: Нет | R40: Нет | S40: Да | T40: =IF($G40="Москва",1.3*(IF(IF(I40="Да",1,0)=1,1.4*Лист2!AX$1,Лист2!AX$1)),(IF(IF(I40="Да",1,0)=1,1.4*Лист2!AX$1,Лист2!AX$1))) -> 305.30769 | U40: =IF($G40="Москва",1.3*(IF(IF(J40="Да",1,0)=1,1.4*Лист2!AY$1,Лист2!AY$1)),(IF(IF(J40="Да",1,0)=1,1.4*Лист2!AY$1,Лист2!AY$1))) -> 192.30769 | V40: =IF($G40="Москва",1.3*(IF(IF(K40="Да",1,0)=1,1.4*Лист2!AZ$1,Лист2!AZ$1)),(IF(IF(K40="Да",1,0)=1,1.4*Лист2!AZ$1,Лист2!AZ$1))) -> 920.76923 | W40: =IF($G40="Москва",1.3*(IF(IF(L40="Да",1,0)=1,1.4*Лист2!BA$1,Лист2!BA$1)),(IF(IF(L40="Да",1,0)=1,1.4*Лист2!BA$1,Лист2!BA$1))) -> 323.07692 | X40: =IF($G40="Москва",1.3*(IF(IF(M40="Да",1,0)=1,1.4*Лист2!BB$1,Лист2!BB$1)),(IF(IF(M40="Да",1,0)=1,1.4*Лист2!BB$1,Лист2!BB$1))) -> 35.384615 | Y40: =IF($G40="Москва",1.3*(IF(IF(N40="Да",1,0)=1,1.4*Лист2!BC$1,Лист2!BC$1)),(IF(IF(N40="Да",1,0)=1,1.4*Лист2!BC$1,Лист2!BC$1))) -> 936.92308 | Z40: =IF($G40="Москва",1.3*(IF(IF(O40="Да",1,0)=1,1.4*Лист2!BD$1,Лист2!BD$1)),(IF(IF(O40="Да",1,0)=1,1.4*Лист2!BD$1,Лист2!BD$1))) -> 242.30769 | AA40: =IF($G40="Москва",1.3*(IF(IF(P40="Да",1,0)=1,1.4*Лист2!BE$1,Лист2!BE$1)),(IF(IF(P40="Да",1,0)=1,1.4*Лист2!BE$1,Лист2!BE$1))) -> 780.76923 | ... AD40: =IF($G40="Москва",1.3*(IF(IF(S40="Да",1,0)=1,1.4*Лист2!BH$1,Лист2!BH$1)),(IF(IF(S40="Да",1,0)=1,1.4*Лист2!BH$1,Лист2!BH$1))) -> 168.26923 | AE40: =SUM(T40:AD40) -> 3983.1923 | AF40: =AE40*4.2 -> 16729.408 | AG40: =AF40*2 -> 33458.815 | AH40: =IF(IF(G40="Москва",1,0)=1,Лист2!$BK$6,Лист2!$BL$6) -> 9230 | AI40: =AH40-AF40 -> -7499.4077 | AJ40: =(H40-AE40)*4.2 -> 67270.592

Sheet Лист3

Sheet Лист2
S1: Мин. потребление в нед | T1: 2.4230769 | U1: 1.9230769 | V1: 2.1923077 | W1: 1.1538462 | X1: 0.44230769 | Y1: 1.1153846 | Z1: 0.34615385 | AA1: 5.5769231 | AB1: 4.0384615 | AC1: 0.21153846 | AD1: 0.096153846 | AJ1: Цена за ед. (₽) | AK1: 90 | AL1: 100 | AM1: 300 | AN1: 200 | AO1: 80 | AP1: 600 | AQ1: 700 | AR1: 100 | AS1: 12 | AT1: 140 | AU1: 1250 | AW1: Цена за ед. (₽) норма | AX1: 218.07692 | AY1: 192.30769 | AZ1: 657.69231 | BA1: 230.76923 | BB1: 35.384615 | BC1: 669.23077 | BD1: 242.30769 | BE1: 557.69231 | BF1: 48.461538 | BG1: 29.615385 | BH1: 120.19231 | BI1: оф. продуктовая Корзина Данные москва | BJ1: оф. Данные по регионам продуктовая Корзина | BK1: 13651 | BL1: 9230
A2: ID | B2: Ваш пол | C2: Ваш возраст | D2: Я веду образ жизни | E2: Вы трудоустроены? | F2: Ваш доход в месяц в рублях? | G2: В каком городе Вы проживаете? | H2: Как Вы считаете, сколько денег Вам нужно в неделю на продукты? | I2: Оцените по шкале необходимость продуктов в Вашем рационе на неделю / Хлебобулочные изделия и крупы | J2: Оцените по шкале необходимость продуктов в Вашем рационе на неделю / Картофель | K2: Оцените по шкале необходимость продуктов в Вашем рационе на неделю / Овощи | L2: Оцените по шкале необходимость продуктов в Вашем рационе на неделю / Фрукты | M2: Оцените по шкале необходимость продуктов в Вашем рационе на неделю / Сахар | N2: Оцените по шкале необходимость продуктов в Вашем рационе на неделю / Мясо | O2: Оцените по шкале необходимость продуктов в Вашем рационе на неделю / Рыба | P2: Оцените по шкале необходимость продуктов в Вашем рационе на неделю / Молочные продукты | Q2: Оцените по шкале необходимость продуктов в Вашем рационе на неделю / Яйца | R2: Оцените по шкале необходимость продуктов в Вашем рационе на неделю / Масло и жиры | S2: Оцените по шкале необходимость продуктов в Вашем рационе на неделю / Чай и специи | T2: Я потребляю в НЕДЕЛЮ больше 1.5 кг хлебобулочных изделий и круп | U2: Я потребляю в НЕДЕЛЮ больше 1.2 кг картофеля | V2: Я потребляю в НЕДЕЛЮ больше 1.3 кг овощей | W2: Я потребляю в НЕДЕЛЮ больше 700 г фруктов | X2: Я потребляю в НЕДЕЛЮ больше 300 г сахара | Y2: Я потребляю в НЕДЕЛЮ больше 700 г мяса (птица тоже считается) | Z2: Я потребляю в НЕДЕЛЮ больше 200 г рыбы | AA2: Я потребляю в НЕДЕЛЮ больше 3.5 кг молочных продуктов (кисломолочка тоже считается) | AB2: Я потребляю в НЕДЕЛЮ больше 3 яиц | AC2: Я потребляю в НЕДЕЛЮ больше 150 г масла и жиров (если потребляете продукты во фритюре, то примерно 20% веса в них - жиры) | AD2: Я потребляю в НЕДЕЛЮ больше 60 г чая и специй | AE2: москва ли (если москва, то =1, если не москва, то =0) | AF2: больше нормы или нет (больше = 1, если вписывается в норму, то =0) | AQ2: сумма траты на продукт в неделю | AR2: Хлебобулочные изделия и крупы | AS2: Картофель | AT2: Овощи | AU2: Фрукты | AV2: Сахар | AW2: Мясо | AX2: Рыба | AY2: Молочные продукты | AZ2: Яйца | BA2: Масло и жиры | BB2: Чай и специи | BC2: сумма в неделю | BD2: сумма в месяц на продукты | BE2: сумма потребительской корзины | BF2: оф данные | BG2: official_difference | BH2: mind_difference
A3: 1995902821 | B3: Жен | C3: 20 | D3: Активный (выхожу из дома не менее 6 дней в неделю) | E3: Да, официально | F3: 60000 | G3: Москва | H3: 7500 | I3: 4 | J3: 6 | K3: 8 | L3: 4 | M3: 4 | N3: 10 | O3: 5 | P3: 7 | Q3: 5 | R3: 5 | S3: 1 | T3: Да | U3: Нет | V3: Да | W3: Нет | X3: Да | Y3: Да | Z3: Нет | AA3: Нет | AB3: Нет | AC3: Да | AD3: Нет | AE3: =IF(G25 = "Москва",1,0) -> 1 | AF3: =IF(T3="Да",1,0) -> 1 | AG3: =IF(U3="Да",1,0) -> 0 | AH3: =IF(V3="Да",1,0) -> 1 | AI3: =IF(W3="Да",1,0) -> 0 | AJ3: =IF(X3="Да",1,0) -> 1 | AK3: =IF(Y3="Да",1,0) -> 1 | AL3: =IF(Z3="Да",1,0) -> 0 | AM3: =IF(AA3="Да",1,0) -> 0 | ... AP3: =IF(AD3="Да",1,0) -> 0 | AR3: =IF($AE3=1,1.3*(IF(AF3=1,1.4*AX$1,AX$1)),(IF(AF3=1,1.4*AX$1,AX$1))) -> 396.9 | AS3: =IF($AE3=1,1.3*(IF(AG3=1,1.4*AY$1,AY$1)),(IF(AG3=1,1.4*AY$1,AY$1))) -> 250 | AT3: =IF($AE3=1,1.3*(IF(AH3=1,1.4*AZ$1,AZ$1)),(IF(AH3=1,1.4*AZ$1,AZ$1))) -> 1197 | AU3: =IF($AE3=1,1.3*(IF(AI3=1,1.4*BA$1,BA$1)),(IF(AI3=1,1.4*BA$1,BA$1))) -> 300 | AV3: =IF($AE3=1,1.3*(IF(AJ3=1,1.4*BB$1,BB$1)),(IF(AJ3=1,1.4*BB$1,BB$1))) -> 64.4 | AW3: =IF($AE3=1,1.3*(IF(AK3=1,1.4*BC$1,BC$1)),(IF(AK3=1,1.4*BC$1,BC$1))) -> 1218 | AX3: =IF($AE3=1,1.3*(IF(AL3=1,1.4*BD$1,BD$1)),(IF(AL3=1,1.4*BD$1,BD$1))) -> 315 | AY3: =IF($AE3=1,1.3*(IF(AM3=1,1.4*BE$1,BE$1)),(IF(AM3=1,1.4*BE$1,BE$1))) -> 725 | ... BB3: =IF($AE3=1,1.3*(IF(AP3=1,1.4*BH$1,BH$1)),(IF(AP3=1,1.4*BH$1,BH$1))) -> 156.25 | BC3: =SUM(AR3:BB3) -> 4739.45 | BD3: =BC3*4.2 -> 19905.69 | BE3: =BD3*2 -> 39811.38 | BF3: =IF(AE3=1,$BK$1,$BL$1) -> 13651 | BG3: =BF3-BD3 -> -6254.69 | BH3: =(H3-BC3)*4.2 -> 11594.31 | BJ3: Мин. потребление в нед | BK3: 2.4230769 | BL3: 1.9230769 | BM3: 2.1923077 | BN3: 1.1538462 | BO3: 0.44230769 | BP3: 1.1153846 | BQ3: 0.34615385 | BR3: 5.5769231 | BS3: 4.0384615 | BT3: 0.21153846 | BU3: 0.096153846 | BV3: Цена за ед. (₽) | BW3: 90 | BX3: 100 | BY3: 300 | BZ3: 200 | CA3: 80 | CB3: 600 | CC3: 700 | CD3: 100 | CE3: 12 | CF3: 140 | CG3: 1250 | CH3: Цена за ед. (₽) норма | CI3: =BK3*BW3 -> 218.07692 | CJ3: =BL3*BX3 -> 192.30769 | CK3: =BM3*BY3 -> 657.69231 | CL3: =BN3*BZ3 -> 230.76923 | CM3: =BO3*CA3 -> 35.384615 | CN3: =BP3*CB3 -> 669.23077 | CO3: =BQ3*CC3 -> 242.30769 | CP3: =BR3*CD3 -> 557.69231 | ... CS3: =BU3*CG3 -> 120.19231
A4: 1996067555 | B4: Муж | C4: 35 | D4: Довольно активный (выхожу из дома не менее 4 дней в неделю) | E4: Да, официально | F4: 30000 | G4: Москва | H4: 8000 | I4: 10 | J4: 7 | K4: 7 | L4: 6 | M4: 2 | N4: 10 | O4: 3 | P4: 6 | Q4: 10 | R4: 4 | S4: 6 | T4: Да | U4: Нет | V4: Нет | W4: Нет | X4: Нет | Y4: Да | Z4: Нет | AA4: Да | AB4: Да | AC4: Нет | AD4: Нет | AE4: 1 | AF4: =IF(T4="Да",1,0) -> 1 | AG4: =IF(U3="Да",1,0) -> 0 | AH4: =IF(V3="Да",1,0) -> 1 | AI4: =IF(W3="Да",1,0) -> 0 | AJ4: =IF(X3="Да",1,0) -> 1 | AK4: =IF(Y3="Да",1,0) -> 1 | AL4: =IF(Z3="Да",1,0) -> 0 | AM4: =IF(AA3="Да",1,0) -> 0 | AN4: =IF(AB3="Да",1,0) -> 0 | ... AP4: =IF(AD3="Да",1,0) -> 0 | AR4: =IF($AE4=1,1.3*(IF(AF4=1,1.4*AX$1,AX$1)),(IF(AF4=1,1.4*AX$1,AX$1))) -> 396.9 | AS4: =IF($AE4=1,1.3*(IF(AG4=1,1.4*AY$1,AY$1)),(IF(AG4=1,1.4*AY$1,AY$1))) -> 250 | AT4: =IF($AE4=1,1.3*(IF(AH4=1,1.4*AZ$1,AZ$1)),(IF(AH4=1,1.4*AZ$1,AZ$1))) -> 1197 | AU4: =IF($AE4=1,1.3*(IF(AI4=1,1.4*BA$1,BA$1)),(IF(AI4=1,1.4*BA$1,BA$1))) -> 300 | AV4: =IF($AE4=1,1.3*(IF(AJ4=1,1.4*BB$1,BB$1)),(IF(AJ4=1,1.4*BB$1,BB$1))) -> 64.4 | AW4: =IF($AE4=1,1.3*(IF(AK4=1,1.4*BC$1,BC$1)),(IF(AK4=1,1.4*BC$1,BC$1))) -> 1218 | AX4: =IF($AE4=1,1.3*(IF(AL4=1,1.4*BD$1,BD$1)),(IF(AL4=1,1.4*BD$1,BD$1))) -> 315 | AY4: =IF($AE4=1,1.3*(IF(AM4=1,1.4*BE$1,BE$1)),(IF(AM4=1,1.4*BE$1,BE$1))) -> 725 | ... BB4: =IF($AE4=1,1.3*(IF(AP4=1,1.4*BH$1,BH$1)),(IF(AP4=1,1.4*BH$1,BH$1))) -> 156.25 | BC4: =SUM(AR4:BB4) -> 4739.45 | BD4: =BC4*4.2 -> 19905.69 | BE4: =BD4*2 -> 39811.38 | BF4: =IF(AE4=1,$BK$1,$BL$1) -> 13651 | BG4: =BF4-BD4 -> -6254.69 | BH4: =(H4-BC4)*4.2 -> 13694.31
A5: 1996071674 | B5: Муж | C5: 20 | D5: Активный (выхожу из дома не менее 6 дней в неделю) | E5: Нет | F5: 60000 | G5: Москва | H5: 8000 | I5: 10 | J5: 10 | K5: 10 | L5: 10 | M5: 10 | N5: 10 | O5: 5 | P5: 10 | Q5: 10 | R5: 5 | S5: 10 | T5: Да | U5: Нет | V5: Да | W5: Нет | X5: Да | Y5: Да | Z5: Нет | AA5: Да | AB5: Да | AC5: Нет | AD5: Да | AE5: =IF(G27 = "Москва",1,0) -> 1 | AF5: =IF(T5="Да",1,0) -> 1 | AG5: =IF(U4="Да",1,0) -> 0 | AH5: =IF(V4="Да",1,0) -> 0 | AI5: =IF(W4="Да",1,0) -> 0 | AJ5: =IF(X4="Да",1,0) -> 0 | AK5: =IF(Y4="Да",1,0) -> 1 | AL5: =IF(Z4="Да",1,0) -> 0 | AM5: =IF(AA4="Да",1,0) -> 1 | AN5: =IF(AB4="Да",1,0) -> 1 | ... AP5: =IF(AD4="Да",1,0) -> 0 | AR5: =IF($AE5=1,1.3*(IF(AF5=1,1.4*AX$1,AX$1)),(IF(AF5=1,1.4*AX$1,AX$1))) -> 396.9 | AS5: =IF($AE5=1,1.3*(IF(AG5=1,1.4*AY$1,AY$1)),(IF(AG5=1,1.4*AY$1,AY$1))) -> 250 | AT5: =IF($AE5=1,1.3*(IF(AH5=1,1.4*AZ$1,AZ$1)),(IF(AH5=1,1.4*AZ$1,AZ$1))) -> 855 | AU5: =IF($AE5=1,1.3*(IF(AI5=1,1.4*BA$1,BA$1)),(IF(AI5=1,1.4*BA$1,BA$1))) -> 300 | AV5: =IF($AE5=1,1.3*(IF(AJ5=1,1.4*BB$1,BB$1)),(IF(AJ5=1,1.4*BB$1,BB$1))) -> 46 | AW5: =IF($AE5=1,1.3*(IF(AK5=1,1.4*BC$1,BC$1)),(IF(AK5=1,1.4*BC$1,BC$1))) -> 1218 | AX5: =IF($AE5=1,1.3*(IF(AL5=1,1.4*BD$1,BD$1)),(IF(AL5=1,1.4*BD$1,BD$1))) -> 315 | AY5: =IF($AE5=1,1.3*(IF(AM5=1,1.4*BE$1,BE$1)),(IF(AM5=1,1.4*BE$1,BE$1))) -> 1015 | ... BB5: =IF($AE5=1,1.3*(IF(AP5=1,1.4*BH$1,BH$1)),(IF(AP5=1,1.4*BH$1,BH$1))) -> 156.25 | BC5: =SUM(AR5:BB5) -> 4678.85 | BD5: =BC5*4.2 -> 19651.17 | BE5: =BD5*2 -> 39302.34 | BF5: =IF(AE5=1,$BK$1,$BL$1) -> 13651 | BG5: =BF5-BD5 -> -6000.17 | BH5: =(H5-BC5)*4.2 -> 13948.83 | BK5: оф. продуктовая Корзина Данные москва | BL5: оф. Данные по регионам продуктовая Корзина
A6: 1996073501 | B6: Муж | C6: 20 | D6: Активный (выхожу из дома не менее 6 дней в неделю) | E6: Да, официально | F6: 60000 | G6: Саратов, Саратовская область | H6: 4000 | I6: 7 | J6: 2 | K6: 7 | L6: 10 | M6: 6 | N6: 10 | O6: 8 | P6: 7 | Q6: 10 | R6: 1 | S6: 3 | T6: Да | U6: Нет | V6: Да | W6: Да | X6: Нет | Y6: Да | Z6: Да | AA6: Нет | AB6: Да | AC6: Нет | AD6: Нет | AE6: =IF(G28 = "Москва",1,0) -> 1 | AF6: =IF(T6="Да",1,0) -> 1 | AG6: =IF(U5="Да",1,0) -> 0 | AH6: =IF(V5="Да",1,0) -> 1 | AI6: =IF(W5="Да",1,0) -> 0 | AJ6: =IF(X5="Да",1,0) -> 1 | AK6: =IF(Y5="Да",1,0) -> 1 | AL6: =IF(Z5="Да",1,0) -> 0 | AM6: =IF(AA5="Да",1,0) -> 1 | AN6: =IF(AB5="Да",1,0) -> 1 | ... AP6: =IF(AD5="Да",1,0) -> 1 | AR6: =IF($AE6=1,1.3*(IF(AF6=1,1.4*AX$1,AX$1)),(IF(AF6=1,1.4*AX$1,AX$1))) -> 396.9 | AS6: =IF($AE6=1,1.3*(IF(AG6=1,1.4*AY$1,AY$1)),(IF(AG6=1,1.4*AY$1,AY$1))) -> 250 | AT6: =IF($AE6=1,1.3*(IF(AH6=1,1.4*AZ$1,AZ$1)),(IF(AH6=1,1.4*AZ$1,AZ$1))) -> 1197 | AU6: =IF($AE6=1,1.3*(IF(AI6=1,1.4*BA$1,BA$1)),(IF(AI6=1,1.4*BA$1,BA$1))) -> 300 | AV6: =IF($AE6=1,1.3*(IF(AJ6=1,1.4*BB$1,BB$1)),(IF(AJ6=1,1.4*BB$1,BB$1))) -> 64.4 | AW6: =IF($AE6=1,1.3*(IF(AK6=1,1.4*BC$1,BC$1)),(IF(AK6=1,1.4*BC$1,BC$1))) -> 1218 | AX6: =IF($AE6=1,1.3*(IF(AL6=1,1.4*BD$1,BD$1)),(IF(AL6=1,1.4*BD$1,BD$1))) -> 315 | AY6: =IF($AE6=1,1.3*(IF(AM6=1,1.4*BE$1,BE$1)),(IF(AM6=1,1.4*BE$1,BE$1))) -> 1015 | ... BB6: =IF($AE6=1,1.3*(IF(AP6=1,1.4*BH$1,BH$1)),(IF(AP6=1,1.4*BH$1,BH$1))) -> 218.75 | BC6: =SUM(AR6:BB6) -> 5101.75 | BD6: =BC6*4.2 -> 21427.35 | BE6: =BD6*2 -> 42854.7 | BF6: =IF(AE6=1,$BK$1,$BL$1) -> 13651 | BG6: =BF6-BD6 -> -7776.35 | BH6: =(H6-BC6)*4.2 -> -4627.35 | BK6: 13651 | BL6: 9230
